Workbook

Sheet 설정
A1: 밸런스 시뮬레이터 설정 — 노란 칸을 고치고 저장한 뒤 python Tools/balance_sim_xlsx.py | Z1: v2
A2: 층별 시트는 엑셀 수식이라 바로 바뀜 · 요약/판 시트는 스크립트를 다시 돌려야 바뀜
A3: 항목 | B3: 키 | C3: 값 | D3: 설명
A4: 기본 제한시간 (초) | B4: BASE_TIME | C4: 120 | D4: RunTimer.baseTime
A5: 시간 배율 C | B5: TIME_C | C5: 0.8 | D5: 층 시간 = 목표 초 × C × r^-지수 (r = 전투력 ÷ 적정)
A6: r<1 지수 | B6: TIME_LO | C6: 1.5 | D6: 전투력이 모자랄 때 느려지는 정도
A7: r≥1 지수 | B7: TIME_HI | C7: 0.5 | D7: 전투력이 넘칠 때 빨라지는 정도
A8: 클릭 거의 안 함: 층 시간 배율 | B8: PASSIVE_SLOW | C8: 1.35 | D8: 같은 상태에서 몇 배 느린지 (측정 필요 — 지금은 가정)
A9: 층 사이 연출 (초) | B9: FLOOR_OVERHEAD | C9: 6
A10: 판마다 로비 시간 (초) | B10: RUN_OVERHEAD | C10: 75
A11: 판 첫 층 손해 (초) | B11: RAMP_SEC | C11: 25 | D11: 쥐가 불어나는 동안
A12: 16층~ 훈장·트리에 쓰는 수입 몫 | B12: LATE_SHARE | C12: 0.5 | D12: 나머지 = 뽑기·상점·증강 강화
A13: 층당 출생 ÷ 최대 마릿수 | B13: BIRTH_PER_POP | C13: 1 | D13: 조각 = 태어난 종 +1 (조각 합·도감 조건). 레벨업 조각 = 쥐 등급 테이블 shard_k
A14: 증강 1칸당 전투력 + | B14: AUG_PER_SLOT | C14: 0.08 | D14: 31층~ (gen_stage_table 과 같게)
A15: 시뮬 최대 시간 (h) | B15: HOURS_CAP | C15: 60 | D15: 못 깨면 여기서 멈춤
A16: 목표: 클릭 적극 (h) | B16: GOAL_ACTIVE | C16: 10 | D16: 사용자 2026-10-19
A17: 목표: 거의 안 함 (h) | B17: GOAL_PASSIVE | C17: 15
A20: 훈장별 (전투력 = BalanceProbe 측정 Tools/probe_results/power_by_tier.json · 추가 비용 배율 = 테이블 비용에 더 곱함, 1 = 그대로)
A21: 훈장 | B21: 시작 전투력 | C21: 끝 전투력 | D21: 추가 비용 배율 | E21: 증강 슬롯 | F21: 제한시간 + (누적) | G21: 보스 층 + (누적) | H21: 승급 연구자료 (테이블) | I21: 조건 층 | J21: 최대 마릿수
A22: 1 | B22: 500 | C22: 1500 | D22: 1 | E22: 5 | F22: 4 | G22: 4 | H22: 0 | I22: 0 | J22: 40
A23: 2 | B23: 1575 | C23: 2900 | D23: 1 | E23: 5 | F23: 8 | G23: 8 | H23: 220 | I23: 6 | J23: 50
A24: 3 | B24: 3045 | C24: 5500 | D24: 1 | E24: 5 | F24: 14 | G24: 12 | H24: 210 | I24: 9 | J24: 65
A25: 4 | B25: 5775 | C25: 10900 | D25: 1 | E25: 5 | F25: 22 | G25: 16 | H25: 260 | I25: 11 | J25: 80
A26: 5 | B26: 11445 | C26: 26200 | D26: 1 | E26: 5 | F26: 30 | G26: 20 | H26: 560 | I26: 14 | J26: 96
A27: 6 | B27: 27510 | C27: 57700 | D27: 1 | E27: 5 | F27: 38 | G27: 24 | H27: 770 | I27: 16 | J27: 102
A28: 7 | B28: 60585 | C28: 217000 | D28: 1 | E28: 5 | F28: 48 | G28: 27 | H28: 2420 | I28: 18 | J28: 141
A29: 8 | B29: 227850 | C29: 400000 | D29: 1 | E29: 5 | F29: 60 | G29: 30 | H29: 9920 | I29: 20 | J29: 155
A30: 9 | B30: 420000 | C30: 560000 | D30: 1 | E30: 5 | F30: 60 | G30: 33 | H30: 42000 | I30: 31 | J30: 180
A31: 10 | B31: 588000 | C31: 2100000 | D31: 1 | E31: 6 | F31: 60 | G31: 36 | H31: 87000 | I31: 41 | J31: 210
A32: 11 | B32: 2205000 | C32: 4670000 | D32: 1 | E32: 6 | F32: 60 | G32: 39 | H32: 328000 | I32: 51 | J32: 250
A33: 12 | B33: 4903500 | C33: 11600000 | D33: 1 | E33: 7 | F33: 60 | G33: 42 | H33: 742000 | I33: 61 | J33: 295
... A37: 16 | B37: 48090000 | C37: 64000000 | D37: 1 | E37: 8 | F37: 60 | G37: 54 | H37: 11154000 | I37: 100 | J37: 525

Sheet 요약
A1: 시뮬레이션 결과 (이 시트는 스크립트가 덮어씀)
B3: 클릭 적극 | C3: 거의 안 함
A4: 총 시간 (h) | B4: 10.79 | C4: 14.52
A5: 목표 (h) | B5: 10 | C5: 15
A6: 판 수 | B6: 41 | C6: 53
A7: 판 평균 (분) | B7: 15.79 | C7: 16.43
A8: 최고 층 | B8: 100 | C8: 100
A9: 마지막 훈장 | B9: 15 | C9: 15
A10: 16층 클리어 (h) | B10: 2.15 | C10: 2.57
A11: 30층 클리어 (h) | B11: 4.17 | C11: 6.36
A12: 31층 클리어 (h) | B12: 4.17 | C12: 6.36
A13: 41층 클리어 (h) | B13: 4.71 | C13: 7.28
A14: 50층 클리어 (h) | B14: 6.39 | C14: 9.17
A15: 70층 클리어 (h) | B15: 8.36 | C15: 11.74
... A29: 100층에서 막힌 판 | B29: 4 | C29: 3
A31: 시간표 목표(누적, 사용자 2026-10-19): 튜토리얼 ~20분 · 16층 2h · 30층 4h · 31층 증강 4h · 50층 6.5h · 70층 9h · 100층 12.5h · 허들 층 2~3판

Sheet 층별
A1: 훈장 끝 상태(트리 전부)로 이 층을 깨는 데 걸리는 초 (수식) — 빨강 = 실패 · 주황 = 제한시간 85%↑ · 초록 = 40%↓ · 굵은 행 = 허들 층
A2: 층 | B2: 유형 | C2: 보스 | D2: 적정 전투력 | E2: 목표 초 | F2: 연구자료 | G2: 시작 층 상한 | H2: 1훈장 | I2: 2훈장 | J2: 3훈장 | K2: 4훈장 | L2: 5훈장 | M2: 6훈장 | N2: 7훈장 | O2: 8훈장 | P2: 9훈장 | Q2: 10훈장 | R2: 11훈장 | S2: 12훈장 | T2: 13훈장 | U2: 14훈장 | V2: 15훈장 | W2: 16훈장
A3: 1 | B3: 도입 | D3: 300 | E3: 72 | F3: 8 | G3: 1 | H3: =IF($E3*'설정'!$C$5*IF(('설정'!$C$22*IF($A3>=31,1+'설정'!$C$14*'설정'!$E$22,1)/$D3)<1,('설정'!$C$22*IF($A3>=31,1+'설정'!$C$14*'설정'!$E$22,1)/$D3)^(-'설정'!$C$6),('설정'!$C$22*IF($A3>=31,1+'설정'!$C$14*'설정'!$E$22,1)/$D3)^(-'설정'!$C$7))>('설정'!$C$4+'설정'!$F$22),"실패",ROUND($E3*'설정'!$C$5*IF(('설정'!$C$22*IF($A3>=31,1+'설정'!$C$14*'설정'!$E$22,1)/$D3)<1,('설정'!$C$22*IF($A3>=31,1+'설정'!$C$14*'설정'!$E$22,1)/$D3)^(-'설정'!$C$6),('설정'!$C$22*IF($A3>=31,1+'설정'!$C$14*'설정'!$E$22,1)/$D3)^(-'설정'!$C$7)),0)) | I3: =IF($E3*'설정'!$C$5*IF(('설정'!$C$23*IF($A3>=31,1+'설정'!$C$14*'설정'!$E$23,1)/$D3)<1,('설정'!$C$23*IF($A3>=31,1+'설정'!$C$14*'설정'!$E$23,1)/$D3)^(-'설정'!$C$6),('설정'!$C$23*IF($A3>=31,1+'설정'!$C$14*'설정'!$E$23,1)/$D3)^(-'설정'!$C$7))>('설정'!$C$4+'설정'!$F$23),"실패",ROUND($E3*'설정'!$C$5*IF(('설정'!$C$23*IF($A3>=31,1+'설정'!$C$14*'설정'!$E$23,1)/$D3)<1,('설정'!$C$23*IF($A3>=31,1+'설정'!$C$14*'설정'!$E$23,1)/$D3)^(-'설정'!$C$6),('설정'!$C$23*IF($A3>=31,1+'설정'!$C$14*'설정'!$E$23,1)/$D3)^(-'설정'!$C$7)),0)) | J3: =IF($E3*'설정'!$C$5*IF(('설정'!$C$24*IF($A3>=31,1+'설정'!$C$14*'설정'!$E$24,1)/$D3)<1,('설정'!$C$24*IF($A3>=31,1+'설정'!$C$14*'설정'!$E$24,1)/$D3)^(-'설정'!$C$6),('설정'!$C$24*IF($A3>=31,1+'설정'!$C$14*'설정'!$E$24,1)/$D3)^(-'설정'!$C$7))>('설정'!$C$4+'설정'!$F$24),"실패",ROUND($E3*'설정'!$C$5*IF(('설정'!$C$24*IF($A3>=31,1+'설정'!$C$14*'설정'!$E$24,1)/$D3)<1,('설정'!$C$24*IF($A3>=31,1+'설정'!$C$14*'설정'!$E$24,1)/$D3)^(-'설정'!$C$6),('설정'!$C$24*IF($A3>=31,1+'설정'!$C$14*'설정'!$E$24,1)/$D3)^(-'설정'!$C$7)),0)) | K3: =IF($E3*'설정'!$C$5*IF(('설정'!$C$25*IF($A3>=31,1+'설정'!$C$14*'설정'!$E$25,1)/$D3)<1,('설정'!$C$25*IF($A3>=31,1+'설정'!$C$14*'설정'!$E$25,1)/$D3)^(-'설정'!$C$6),('설정'!$C$25*IF($A3>=31,1+'설정'!$C$14*'설정'!$E$25,1)/$D3)^(-'설정'!$C$7))>('설정'!$C$4+'설정'!$F$25),"실패",ROUND($E3*'설정'!$C$5*IF(('설정'!$C$25*IF($A3>=31,1+'설정'!$C$14*'설정'!$E$25,1)/$D3)<1,('설정'!$C$25*IF($A3>=31,1+'설정'!$C$14*'설정'!$E$25,1)/$D3)^(-'설정'!$C$6),('설정'!$C$25*IF($A3>=31,1+'설정'!$C$14*'설정'!$E$25,1)/$D3)^(-'설정'!$C$7)),0)) | L3: =IF($E3*'설정'!$C$5*IF(('설정'!$C$26*IF($A3>=31,1+'설정'!$C$14*'설정'!$E$26,1)/$D3)<1,('설정'!$C$26*IF($A3>=31,1+'설정'!$C$14*'설정'!$E$26,1)/$D3)^(-'설정'!$C$6),('설정'!$C$26*IF($A3>=31,1+'설정'!$C$14*'설정'!$E$26,1)/$D3)^(-'설정'!$C$7))>('설정'!$C$4+'설정'!$F$26),"실패",ROUND($E3*'설정'!$C$5*IF(('설정'!$C$26*IF($A3>=31,1+'설정'!$C$14*'설정'!$E$26,1)/$D3)<1,('설정'!$C$26*IF($A3>=31,1+'설정'!$C$14*'설정'!$E$26,1)/$D3)^(-'설정'!$C$6),('설정'!$C$26*IF($A3>=31,1+'설정'!$C$14*'설정'!$E$26,1)/$D3)^(-'설정'!$C$7)),0)) | M3: =IF($E3*'설정'!$C$5*IF(('설정'!$C$27*IF($A3>=31,1+'설정'!$C$14*'설정'!$E$27,1)/$D3)<1,('설정'!$C$27*IF($A3>=31,1+'설정'!$C$14*'설정'!$E$27,1)/$D3)^(-'설정'!$C$6),('설정'!$C$27*IF($A3>=31,1+'설정'!$C$14*'설정'!$E$27,1)/$D3)^(-'설정'!$C$7))>('설정'!$C$4+'설정'!$F$27),"실패",ROUND($E3*'설정'!$C$5*IF(('설정'!$C$27*IF($A3>=31,1+'설정'!$C$14*'설정'!$E$27,1)/$D3)<1,('설정'!$C$27*IF($A3>=31,1+'설정'!$C$14*'설정'!$E$27,1)/$D3)^(-'설정'!$C$6),('설정'!$C$27*IF($A3>=31,1+'설정'!$C$14*'설정'!$E$27,1)/$D3)^(-'설정'!$C$7)),0)) | N3: =IF($E3*'설정'!$C$5*IF(('설정'!$C$28*IF($A3>=31,1+'설정'!$C$14*'설정'!$E$28,1)/$D3)<1,('설정'!$C$28*IF($A3>=31,1+'설정'!$C$14*'설정'!$E$28,1)/$D3)^(-'설정'!$C$6),('설정'!$C$28*IF($A3>=31,1+'설정'!$C$14*'설정'!$E$28,1)/$D3)^(-'설정'!$C$7))>('설정'!$C$4+'설정'!$F$28),"실패",ROUND($E3*'설정'!$C$5*IF(('설정'!$C$28*IF($A3>=31,1+'설정'!$C$14*'설정'!$E$28,1)/$D3)<1,('설정'!$C$28*IF($A3>=31,1+'설정'!$C$14*'설정'!$E$28,1)/$D3)^(-'설정'!$C$6),('설정'!$C$28*IF($A3>=31,1+'설정'!$C$14*'설정'!$E$28,1)/$D3)^(-'설정'!$C$7)),0)) | O3: =IF($E3*'설정'!$C$5*IF(('설정'!$C$29*IF($A3>=31,1+'설정'!$C$14*'설정'!$E$29,1)/$D3)<1,('설정'!$C$29*IF($A3>=31,1+'설정'!$C$14*'설정'!$E$29,1)/$D3)^(-'설정'!$C$6),('설정'!$C$29*IF($A3>=31,1+'설정'!$C$14*'설정'!$E$29,1)/$D3)^(-'설정'!$C$7))>('설정'!$C$4+'설정'!$F$29),"실패",ROUND($E3*'설정'!$C$5*IF(('설정'!$C$29*IF($A3>=31,1+'설정'!$C$14*'설정'!$E$29,1)/$D3)<1,('설정'!$C$29*IF($A3>=31,1+'설정'!$C$14*'설정'!$E$29,1)/$D3)^(-'설정'!$C$6),('설정'!$C$29*IF($A3>=31,1+'설정'!$C$14*'설정'!$E$29,1)/$D3)^(-'설정'!$C$7)),0)) | P3: =IF($E3*'설정'!$C$5*IF(('설정'!$C$30*IF($A3>=31,1+'설정'!$C$14*'설정'!$E$30,1)/$D3)<1,('설정'!$C$30*IF($A3>=31,1+'설정'!$C$14*'설정'!$E$30,1)/$D3)^(-'설정'!$C$6),('설정'!$C$30*IF($A3>=31,1+'설정'!$C$14*'설정'!$E$30,1)/$D3)^(-'설정'!$C$7))>('설정'!$C$4+'설정'!$F$30),"실패",ROUND($E3*'설정'!$C$5*IF(('설정'!$C$30*IF($A3>=31,1+'설정'!$C$14*'설정'!$E$30,1)/$D3)<1,('설정'!$C$30*IF($A3>=31,1+'설정'!$C$14*'설정'!$E$30,1)/$D3)^(-'설정'!$C$6),('설정'!$C$30*IF($A3>=31,1+'설정'!$C$14*'설정'!$E$30,1)/$D3)^(-'설정'!$C$7)),0)) | Q3: =IF($E3*'설정'!$C$5*IF(('설정'!$C$31*IF($A3>=31,1+'설정'!$C$14*'설정'!$E$31,1)/$D3)<1,('설정'!$C$31*IF($A3>=31,1+'설정'!$C$14*'설정'!$E$31,1)/$D3)^(-'설정'!$C$6),('설정'!$C$31*IF($A3>=31,1+'설정'!$C$14*'설정'!$E$31,1)/$D3)^(-'설정'!$C$7))>('설정'!$C$4+'설정'!$F$31),"실패",ROUND($E3*'설정'!$C$5*IF(('설정'!$C$31*IF($A3>=31,1+'설정'!$C$14*'설정'!$E$31,1)/$D3)<1,('설정'!$C$31*IF($A3>=31,1+'설정'!$C$14*'설정'!$E$31,1)/$D3)^(-'설정'!$C$6),('설정'!$C$31*IF($A3>=31,1+'설정'!$C$14*'설정'!$E$31,1)/$D3)^(-'설정'!$C$7)),0)) | R3: =IF($E3*'설정'!$C$5*IF(('설정'!$C$32*IF($A3>=31,1+'설정'!$C$14*'설정'!$E$32,1)/$D3)<1,('설정'!$C$32*IF($A3>=31,1+'설정'!$C$14*'설정'!$E$32,1)/$D3)^(-'설정'!$C$6),('설정'!$C$32*IF($A3>=31,1+'설정'!$C$14*'설정'!$E$32,1)/$D3)^(-'설정'!$C$7))>('설정'!$C$4+'설정'!$F$32),"실패",ROUND($E3*'설정'!$C$5*IF(('설정'!$C$32*IF($A3>=31,1+'설정'!$C$14*'설정'!$E$32,1)/$D3)<1,('설정'!$C$32*IF($A3>=31,1+'설정'!$C$14*'설정'!$E$32,1)/$D3)^(-'설정'!$C$6),('설정'!$C$32*IF($A3>=31,1+'설정'!$C$14*'설정'!$E$32,1)/$D3)^(-'설정'!$C$7)),0)) | S3: =IF($E3*'설정'!$C$5*IF(('설정'!$C$33*IF($A3>=31,1+'설정'!$C$14*'설정'!$E$33,1)/$D3)<1,('설정'!$C$33*IF($A3>=31,1+'설정'!$C$14*'설정'!$E$33,1)/$D3)^(-'설정'!$C$6),('설정'!$C$33*IF($A3>=31,1+'설정'!$C$14*'설정'!$E$33,1)/$D3)^(-'설정'!$C$7))>('설정'!$C$4+'설정'!$F$33),"실패",ROUND($E3*'설정'!$C$5*IF(('설정'!$C$33*IF($A3>=31,1+'설정'!$C$14*'설정'!$E$33,1)/$D3)<1,('설정'!$C$33*IF($A3>=31,1+'설정'!$C$14*'설정'!$E$33,1)/$D3)^(-'설정'!$C$6),('설정'!$C$33*IF($A3>=31,1+'설정'!$C$14*'설정'!$E$33,1)/$D3)^(-'설정'!$C$7)),0)) | T3: =IF($E3*'설정'!$C$5*IF(('설정'!$C$34*IF($A3>=31,1+'설정'!$C$14*'설정'!$E$34,1)/$D3)<1,('설정'!$C$34*IF($A3>=31,1+'설정'!$C$14*'설정'!$E$34,1)/$D3)^(-'설정'!$C$6),('설정'!$C$34*IF($A3>=31,1+'설정'!$C$14*'설정'!$E$34,1)/$D3)^(-'설정'!$C$7))>('설정'!$C$4+'설정'!$F$34),"실패",ROUND($E3*'설정'!$C$5*IF(('설정'!$C$34*IF($A3>=31,1+'설정'!$C$14*'설정'!$E$34,1)/$D3)<1,('설정'!$C$34*IF($A3>=31,1+'설정'!$C$14*'설정'!$E$34,1)/$D3)^(-'설정'!$C$6),('설정'!$C$34*IF($A3>=31,1+'설정'!$C$14*'설정'!$E$34,1)/$D3)^(-'설정'!$C$7)),0)) | U3: =IF($E3*'설정'!$C$5*IF(('설정'!$C$35*IF($A3>=31,1+'설정'!$C$14*'설정'!$E$35,1)/$D3)<1,('설정'!$C$35*IF($A3>=31,1+'설정'!$C$14*'설정'!$E$35,1)/$D3)^(-'설정'!$C$6),('설정'!$C$35*IF($A3>=31,1+'설정'!$C$14*'설정'!$E$35,1)/$D3)^(-'설정'!$C$7))>('설정'!$C$4+'설정'!$F$35),"실패",ROUND($E3*'설정'!$C$5*IF(('설정'!$C$35*IF($A3>=31,1+'설정'!$C$14*'설정'!$E$35,1)/$D3)<1,('설정'!$C$35*IF($A3>=31,1+'설정'!$C$14*'설정'!$E$35,1)/$D3)^(-'설정'!$C$6),('설정'!$C$35*IF($A3>=31,1+'설정'!$C$14*'설정'!$E$35,1)/$D3)^(-'설정'!$C$7)),0)) | V3: =IF($E3*'설정'!$C$5*IF(('설정'!$C$36*IF($A3>=31,1+'설정'!$C$14*'설정'!$E$36,1)/$D3)<1,('설정'!$C$36*IF($A3>=31,1+'설정'!$C$14*'설정'!$E$36,1)/$D3)^(-'설정'!$C$6),('설정'!$C$36*IF($A3>=31,1+'설정'!$C$14*'설정'!$E$36,1)/$D3)^(-'설정'!$C$7))>('설정'!$C$4+'설정'!$F$36),"실패",ROUND($E3*'설정'!$C$5*IF(('설정'!$C$36*IF($A3>=31,1+'설정'!$C$14*'설정'!$E$36,1)/$D3)<1,('설정'!$C$36*IF($A3>=31,1+'설정'!$C$14*'설정'!$E$36,1)/$D3)^(-'설정'!$C$6),('설정'!$C$36*IF($A3>=31,1+'설정'!$C$14*'설정'!$E$36,1)/$D3)^(-'설정'!$C$7)),0)) | W3: =IF($E3*'설정'!$C$5*IF(('설정'!$C$37*IF($A3>=31,1+'설정'!$C$14*'설정'!$E$37,1)/$D3)<1,('설정'!$C$37*IF($A3>=31,1+'설정'!$C$14*'설정'!$E$37,1)/$D3)^(-'설정'!$C$6),('설정'!$C$37*IF($A3>=31,1+'설정'!$C$14*'설정'!$E$37,1)/$D3)^(-'설정'!$C$7))>('설정'!$C$4+'설정'!$F$37),"실패",ROUND($E3*'설정'!$C$5*IF(('설정'!$C$37*IF($A3>=31,1+'설정'!$C$14*'설정'!$E$37,1)/$D3)<1,('설정'!$C$37*IF($A3>=31,1+'설정'!$C$14*'설정'!$E$37,1)/$D3)^(-'설정'!$C$6),('설정'!$C$37*IF($A3>=31,1+'설정'!$C$14*'설정'!$E$37,1)/$D3)^(-'설정'!$C$7)),0))
A4: 2 | B4: 쉬움 | D4: 500 | E4: 72 | F4: 10 | G4: 1 | H4: =IF($E4*'설정'!$C$5*IF(('설정'!$C$22*IF($A4>=31,1+'설정'!$C$14*'설정'!$E$22,1)/$D4)<1,('설정'!$C$22*IF($A4>=31,1+'설정'!$C$14*'설정'!$E$22,1)/$D4)^(-'설정'!$C$6),('설정'!$C$22*IF($A4>=31,1+'설정'!$C$14*'설정'!$E$22,1)/$D4)^(-'설정'!$C$7))>('설정'!$C$4+'설정'!$F$22),"실패",ROUND($E4*'설정'!$C$5*IF(('설정'!$C$22*IF($A4>=31,1+'설정'!$C$14*'설정'!$E$22,1)/$D4)<1,('설정'!$C$22*IF($A4>=31,1+'설정'!$C$14*'설정'!$E$22,1)/$D4)^(-'설정'!$C$6),('설정'!$C$22*IF($A4>=31,1+'설정'!$C$14*'설정'!$E$22,1)/$D4)^(-'설정'!$C$7)),0)) | I4: =IF($E4*'설정'!$C$5*IF(('설정'!$C$23*IF($A4>=31,1+'설정'!$C$14*'설정'!$E$23,1)/$D4)<1,('설정'!$C$23*IF($A4>=31,1+'설정'!$C$14*'설정'!$E$23,1)/$D4)^(-'설정'!$C$6),('설정'!$C$23*IF($A4>=31,1+'설정'!$C$14*'설정'!$E$23,1)/$D4)^(-'설정'!$C$7))>('설정'!$C$4+'설정'!$F$23),"실패",ROUND($E4*'설정'!$C$5*IF(('설정'!$C$23*IF($A4>=31,1+'설정'!$C$14*'설정'!$E$23,1)/$D4)<1,('설정'!$C$23*IF($A4>=31,1+'설정'!$C$14*'설정'!$E$23,1)/$D4)^(-'설정'!$C$6),('설정'!$C$23*IF($A4>=31,1+'설정'!$C$14*'설정'!$E$23,1)/$D4)^(-'설정'!$C$7)),0)) | J4: =IF($E4*'설정'!$C$5*IF(('설정'!$C$24*IF($A4>=31,1+'설정'!$C$14*'설정'!$E$24,1)/$D4)<1,('설정'!$C$24*IF($A4>=31,1+'설정'!$C$14*'설정'!$E$24,1)/$D4)^(-'설정'!$C$6),('설정'!$C$24*IF($A4>=31,1+'설정'!$C$14*'설정'!$E$24,1)/$D4)^(-'설정'!$C$7))>('설정'!$C$4+'설정'!$F$24),"실패",ROUND($E4*'설정'!$C$5*IF(('설정'!$C$24*IF($A4>=31,1+'설정'!$C$14*'설정'!$E$24,1)/$D4)<1,('설정'!$C$24*IF($A4>=31,1+'설정'!$C$14*'설정'!$E$24,1)/$D4)^(-'설정'!$C$6),('설정'!$C$24*IF($A4>=31,1+'설정'!$C$14*'설정'!$E$24,1)/$D4)^(-'설정'!$C$7)),0)) | K4: =IF($E4*'설정'!$C$5*IF(('설정'!$C$25*IF($A4>=31,1+'설정'!$C$14*'설정'!$E$25,1)/$D4)<1,('설정'!$C$25*IF($A4>=31,1+'설정'!$C$14*'설정'!$E$25,1)/$D4)^(-'설정'!$C$6),('설정'!$C$25*IF($A4>=31,1+'설정'!$C$14*'설정'!$E$25,1)/$D4)^(-'설정'!$C$7))>('설정'!$C$4+'설정'!$F$25),"실패",ROUND($E4*'설정'!$C$5*IF(('설정'!$C$25*IF($A4>=31,1+'설정'!$C$14*'설정'!$E$25,1)/$D4)<1,('설정'!$C$25*IF($A4>=31,1+'설정'!$C$14*'설정'!$E$25,1)/$D4)^(-'설정'!$C$6),('설정'!$C$25*IF($A4>=31,1+'설정'!$C$14*'설정'!$E$25,1)/$D4)^(-'설정'!$C$7)),0)) | L4: =IF($E4*'설정'!$C$5*IF(('설정'!$C$26*IF($A4>=31,1+'설정'!$C$14*'설정'!$E$26,1)/$D4)<1,('설정'!$C$26*IF($A4>=31,1+'설정'!$C$14*'설정'!$E$26,1)/$D4)^(-'설정'!$C$6),('설정'!$C$26*IF($A4>=31,1+'설정'!$C$14*'설정'!$E$26,1)/$D4)^(-'설정'!$C$7))>('설정'!$C$4+'설정'!$F$26),"실패",ROUND($E4*'설정'!$C$5*IF(('설정'!$C$26*IF($A4>=31,1+'설정'!$C$14*'설정'!$E$26,1)/$D4)<1,('설정'!$C$26*IF($A4>=31,1+'설정'!$C$14*'설정'!$E$26,1)/$D4)^(-'설정'!$C$6),('설정'!$C$26*IF($A4>=31,1+'설정'!$C$14*'설정'!$E$26,1)/$D4)^(-'설정'!$C$7)),0)) | M4: =IF($E4*'설정'!$C$5*IF(('설정'!$C$27*IF($A4>=31,1+'설정'!$C$14*'설정'!$E$27,1)/$D4)<1,('설정'!$C$27*IF($A4>=31,1+'설정'!$C$14*'설정'!$E$27,1)/$D4)^(-'설정'!$C$6),('설정'!$C$27*IF($A4>=31,1+'설정'!$C$14*'설정'!$E$27,1)/$D4)^(-'설정'!$C$7))>('설정'!$C$4+'설정'!$F$27),"실패",ROUND($E4*'설정'!$C$5*IF(('설정'!$C$27*IF($A4>=31,1+'설정'!$C$14*'설정'!$E$27,1)/$D4)<1,('설정'!$C$27*IF($A4>=31,1+'설정'!$C$14*'설정'!$E$27,1)/$D4)^(-'설정'!$C$6),('설정'!$C$27*IF($A4>=31,1+'설정'!$C$14*'설정'!$E$27,1)/$D4)^(-'설정'!$C$7)),0)) | N4: =IF($E4*'설정'!$C$5*IF(('설정'!$C$28*IF($A4>=31,1+'설정'!$C$14*'설정'!$E$28,1)/$D4)<1,('설정'!$C$28*IF($A4>=31,1+'설정'!$C$14*'설정'!$E$28,1)/$D4)^(-'설정'!$C$6),('설정'!$C$28*IF($A4>=31,1+'설정'!$C$14*'설정'!$E$28,1)/$D4)^(-'설정'!$C$7))>('설정'!$C$4+'설정'!$F$28),"실패",ROUND($E4*'설정'!$C$5*IF(('설정'!$C$28*IF($A4>=31,1+'설정'!$C$14*'설정'!$E$28,1)/$D4)<1,('설정'!$C$28*IF($A4>=31,1+'설정'!$C$14*'설정'!$E$28,1)/$D4)^(-'설정'!$C$6),('설정'!$C$28*IF($A4>=31,1+'설정'!$C$14*'설정'!$E$28,1)/$D4)^(-'설정'!$C$7)),0)) | O4: =IF($E4*'설정'!$C$5*IF(('설정'!$C$29*IF($A4>=31,1+'설정'!$C$14*'설정'!$E$29,1)/$D4)<1,('설정'!$C$29*IF($A4>=31,1+'설정'!$C$14*'설정'!$E$29,1)/$D4)^(-'설정'!$C$6),('설정'!$C$29*IF($A4>=31,1+'설정'!$C$14*'설정'!$E$29,1)/$D4)^(-'설정'!$C$7))>('설정'!$C$4+'설정'!$F$29),"실패",ROUND($E4*'설정'!$C$5*IF(('설정'!$C$29*IF($A4>=31,1+'설정'!$C$14*'설정'!$E$29,1)/$D4)<1,('설정'!$C$29*IF($A4>=31,1+'설정'!$C$14*'설정'!$E$29,1)/$D4)^(-'설정'!$C$6),('설정'!$C$29*IF($A4>=31,1+'설정'!$C$14*'설정'!$E$29,1)/$D4)^(-'설정'!$C$7)),0)) | P4: =IF($E4*'설정'!$C$5*IF(('설정'!$C$30*IF($A4>=31,1+'설정'!$C$14*'설정'!$E$30,1)/$D4)<1,('설정'!$C$30*IF($A4>=31,1+'설정'!$C$14*'설정'!$E$30,1)/$D4)^(-'설정'!$C$6),('설정'!$C$30*IF($A4>=31,1+'설정'!$C$14*'설정'!$E$30,1)/$D4)^(-'설정'!$C$7))>('설정'!$C$4+'설정'!$F$30),"실패",ROUND($E4*'설정'!$C$5*IF(('설정'!$C$30*IF($A4>=31,1+'설정'!$C$14*'설정'!$E$30,1)/$D4)<1,('설정'!$C$30*IF($A4>=31,1+'설정'!$C$14*'설정'!$E$30,1)/$D4)^(-'설정'!$C$6),('설정'!$C$30*IF($A4>=31,1+'설정'!$C$14*'설정'!$E$30,1)/$D4)^(-'설정'!$C$7)),0)) | Q4: =IF($E4*'설정'!$C$5*IF(('설정'!$C$31*IF($A4>=31,1+'설정'!$C$14*'설정'!$E$31,1)/$D4)<1,('설정'!$C$31*IF($A4>=31,1+'설정'!$C$14*'설정'!$E$31,1)/$D4)^(-'설정'!$C$6),('설정'!$C$31*IF($A4>=31,1+'설정'!$C$14*'설정'!$E$31,1)/$D4)^(-'설정'!$C$7))>('설정'!$C$4+'설정'!$F$31),"실패",ROUND($E4*'설정'!$C$5*IF(('설정'!$C$31*IF($A4>=31,1+'설정'!$C$14*'설정'!$E$31,1)/$D4)<1,('설정'!$C$31*IF($A4>=31,1+'설정'!$C$14*'설정'!$E$31,1)/$D4)^(-'설정'!$C$6),('설정'!$C$31*IF($A4>=31,1+'설정'!$C$14*'설정'!$E$31,1)/$D4)^(-'설정'!$C$7)),0)) | R4: =IF($E4*'설정'!$C$5*IF(('설정'!$C$32*IF($A4>=31,1+'설정'!$C$14*'설정'!$E$32,1)/$D4)<1,('설정'!$C$32*IF($A4>=31,1+'설정'!$C$14*'설정'!$E$32,1)/$D4)^(-'설정'!$C$6),('설정'!$C$32*IF($A4>=31,1+'설정'!$C$14*'설정'!$E$32,1)/$D4)^(-'설정'!$C$7))>('설정'!$C$4+'설정'!$F$32),"실패",ROUND($E4*'설정'!$C$5*IF(('설정'!$C$32*IF($A4>=31,1+'설정'!$C$14*'설정'!$E$32,1)/$D4)<1,('설정'!$C$32*IF($A4>=31,1+'설정'!$C$14*'설정'!$E$32,1)/$D4)^(-'설정'!$C$6),('설정'!$C$32*IF($A4>=31,1+'설정'!$C$14*'설정'!$E$32,1)/$D4)^(-'설정'!$C$7)),0)) | S4: =IF($E4*'설정'!$C$5*IF(('설정'!$C$33*IF($A4>=31,1+'설정'!$C$14*'설정'!$E$33,1)/$D4)<1,('설정'!$C$33*IF($A4>=31,1+'설정'!$C$14*'설정'!$E$33,1)/$D4)^(-'설정'!$C$6),('설정'!$C$33*IF($A4>=31,1+'설정'!$C$14*'설정'!$E$33,1)/$D4)^(-'설정'!$C$7))>('설정'!$C$4+'설정'!$F$33),"실패",ROUND($E4*'설정'!$C$5*IF(('설정'!$C$33*IF($A4>=31,1+'설정'!$C$14*'설정'!$E$33,1)/$D4)<1,('설정'!$C$33*IF($A4>=31,1+'설정'!$C$14*'설정'!$E$33,1)/$D4)^(-'설정'!$C$6),('설정'!$C$33*IF($A4>=31,1+'설정'!$C$14*'설정'!$E$33,1)/$D4)^(-'설정'!$C$7)),0)) | T4: =IF($E4*'설정'!$C$5*IF(('설정'!$C$34*IF($A4>=31,1+'설정'!$C$14*'설정'!$E$34,1)/$D4)<1,('설정'!$C$34*IF($A4>=31,1+'설정'!$C$14*'설정'!$E$34,1)/$D4)^(-'설정'!$C$6),('설정'!$C$34*IF($A4>=31,1+'설정'!$C$14*'설정'!$E$34,1)/$D4)^(-'설정'!$C$7))>('설정'!$C$4+'설정'!$F$34),"실패",ROUND($E4*'설정'!$C$5*IF(('설정'!$C$34*IF($A4>=31,1+'설정'!$C$14*'설정'!$E$34,1)/$D4)<1,('설정'!$C$34*IF($A4>=31,1+'설정'!$C$14*'설정'!$E$34,1)/$D4)^(-'설정'!$C$6),('설정'!$C$34*IF($A4>=31,1+'설정'!$C$14*'설정'!$E$34,1)/$D4)^(-'설정'!$C$7)),0)) | U4: =IF($E4*'설정'!$C$5*IF(('설정'!$C$35*IF($A4>=31,1+'설정'!$C$14*'설정'!$E$35,1)/$D4)<1,('설정'!$C$35*IF($A4>=31,1+'설정'!$C$14*'설정'!$E$35,1)/$D4)^(-'설정'!$C$6),('설정'!$C$35*IF($A4>=31,1+'설정'!$C$14*'설정'!$E$35,1)/$D4)^(-'설정'!$C$7))>('설정'!$C$4+'설정'!$F$35),"실패",ROUND($E4*'설정'!$C$5*IF(('설정'!$C$35*IF($A4>=31,1+'설정'!$C$14*'설정'!$E$35,1)/$D4)<1,('설정'!$C$35*IF($A4>=31,1+'설정'!$C$14*'설정'!$E$35,1)/$D4)^(-'설정'!$C$6),('설정'!$C$35*IF($A4>=31,1+'설정'!$C$14*'설정'!$E$35,1)/$D4)^(-'설정'!$C$7)),0)) | V4: =IF($E4*'설정'!$C$5*IF(('설정'!$C$36*IF($A4>=31,1+'설정'!$C$14*'설정'!$E$36,1)/$D4)<1,('설정'!$C$36*IF($A4>=31,1+'설정'!$C$14*'설정'!$E$36,1)/$D4)^(-'설정'!$C$6),('설정'!$C$36*IF($A4>=31,1+'설정'!$C$14*'설정'!$E$36,1)/$D4)^(-'설정'!$C$7))>('설정'!$C$4+'설정'!$F$36),"실패",ROUND($E4*'설정'!$C$5*IF(('설정'!$C$36*IF($A4>=31,1+'설정'!$C$14*'설정'!$E$36,1)/$D4)<1,('설정'!$C$36*IF($A4>=31,1+'설정'!$C$14*'설정'!$E$36,1)/$D4)^(-'설정'!$C$6),('설정'!$C$36*IF($A4>=31,1+'설정'!$C$14*'설정'!$E$36,1)/$D4)^(-'설정'!$C$7)),0)) | W4: =IF($E4*'설정'!$C$5*IF(('설정'!$C$37*IF($A4>=31,1+'설정'!$C$14*'설정'!$E$37,1)/$D4)<1,('설정'!$C$37*IF($A4>=31,1+'설정'!$C$14*'설정'!$E$37,1)/$D4)^(-'설정'!$C$6),('설정'!$C$37*IF($A4>=31,1+'설정'!$C$14*'설정'!$E$37,1)/$D4)^(-'설정'!$C$7))>('설정'!$C$4+'설정'!$F$37),"실패",ROUND($E4*'설정'!$C$5*IF(('설정'!$C$37*IF($A4>=31,1+'설정'!$C$14*'설정'!$E$37,1)/$D4)<1,('설정'!$C$37*IF($A4>=31,1+'설정'!$C$14*'설정'!$E$37,1)/$D4)^(-'설정'!$C$6),('설정'!$C$37*IF($A4>=31,1+'설정'!$C$14*'설정'!$E$37,1)/$D4)^(-'설정'!$C$7)),0))
A5: 3 | B5: 쉬움 | D5: 625 | E5: 72 | F5: 12.5 | G5: 1 | H5: =IF($E5*'설정'!$C$5*IF(('설정'!$C$22*IF($A5>=31,1+'설정'!$C$14*'설정'!$E$22,1)/$D5)<1,('설정'!$C$22*IF($A5>=31,1+'설정'!$C$14*'설정'!$E$22,1)/$D5)^(-'설정'!$C$6),('설정'!$C$22*IF($A5>=31,1+'설정'!$C$14*'설정'!$E$22,1)/$D5)^(-'설정'!$C$7))>('설정'!$C$4+'설정'!$F$22),"실패",ROUND($E5*'설정'!$C$5*IF(('설정'!$C$22*IF($A5>=31,1+'설정'!$C$14*'설정'!$E$22,1)/$D5)<1,('설정'!$C$22*IF($A5>=31,1+'설정'!$C$14*'설정'!$E$22,1)/$D5)^(-'설정'!$C$6),('설정'!$C$22*IF($A5>=31,1+'설정'!$C$14*'설정'!$E$22,1)/$D5)^(-'설정'!$C$7)),0)) | I5: =IF($E5*'설정'!$C$5*IF(('설정'!$C$23*IF($A5>=31,1+'설정'!$C$14*'설정'!$E$23,1)/$D5)<1,('설정'!$C$23*IF($A5>=31,1+'설정'!$C$14*'설정'!$E$23,1)/$D5)^(-'설정'!$C$6),('설정'!$C$23*IF($A5>=31,1+'설정'!$C$14*'설정'!$E$23,1)/$D5)^(-'설정'!$C$7))>('설정'!$C$4+'설정'!$F$23),"실패",ROUND($E5*'설정'!$C$5*IF(('설정'!$C$23*IF($A5>=31,1+'설정'!$C$14*'설정'!$E$23,1)/$D5)<1,('설정'!$C$23*IF($A5>=31,1+'설정'!$C$14*'설정'!$E$23,1)/$D5)^(-'설정'!$C$6),('설정'!$C$23*IF($A5>=31,1+'설정'!$C$14*'설정'!$E$23,1)/$D5)^(-'설정'!$C$7)),0)) | J5: =IF($E5*'설정'!$C$5*IF(('설정'!$C$24*IF($A5>=31,1+'설정'!$C$14*'설정'!$E$24,1)/$D5)<1,('설정'!$C$24*IF($A5>=31,1+'설정'!$C$14*'설정'!$E$24,1)/$D5)^(-'설정'!$C$6),('설정'!$C$24*IF($A5>=31,1+'설정'!$C$14*'설정'!$E$24,1)/$D5)^(-'설정'!$C$7))>('설정'!$C$4+'설정'!$F$24),"실패",ROUND($E5*'설정'!$C$5*IF(('설정'!$C$24*IF($A5>=31,1+'설정'!$C$14*'설정'!$E$24,1)/$D5)<1,('설정'!$C$24*IF($A5>=31,1+'설정'!$C$14*'설정'!$E$24,1)/$D5)^(-'설정'!$C$6),('설정'!$C$24*IF($A5>=31,1+'설정'!$C$14*'설정'!$E$24,1)/$D5)^(-'설정'!$C$7)),0)) | K5: =IF($E5*'설정'!$C$5*IF(('설정'!$C$25*IF($A5>=31,1+'설정'!$C$14*'설정'!$E$25,1)/$D5)<1,('설정'!$C$25*IF($A5>=31,1+'설정'!$C$14*'설정'!$E$25,1)/$D5)^(-'설정'!$C$6),('설정'!$C$25*IF($A5>=31,1+'설정'!$C$14*'설정'!$E$25,1)/$D5)^(-'설정'!$C$7))>('설정'!$C$4+'설정'!$F$25),"실패",ROUND($E5*'설정'!$C$5*IF(('설정'!$C$25*IF($A5>=31,1+'설정'!$C$14*'설정'!$E$25,1)/$D5)<1,('설정'!$C$25*IF($A5>=31,1+'설정'!$C$14*'설정'!$E$25,1)/$D5)^(-'설정'!$C$6),('설정'!$C$25*IF($A5>=31,1+'설정'!$C$14*'설정'!$E$25,1)/$D5)^(-'설정'!$C$7)),0)) | L5: =IF($E5*'설정'!$C$5*IF(('설정'!$C$26*IF($A5>=31,1+'설정'!$C$14*'설정'!$E$26,1)/$D5)<1,('설정'!$C$26*IF($A5>=31,1+'설정'!$C$14*'설정'!$E$26,1)/$D5)^(-'설정'!$C$6),('설정'!$C$26*IF($A5>=31,1+'설정'!$C$14*'설정'!$E$26,1)/$D5)^(-'설정'!$C$7))>('설정'!$C$4+'설정'!$F$26),"실패",ROUND($E5*'설정'!$C$5*IF(('설정'!$C$26*IF($A5>=31,1+'설정'!$C$14*'설정'!$E$26,1)/$D5)<1,('설정'!$C$26*IF($A5>=31,1+'설정'!$C$14*'설정'!$E$26,1)/$D5)^(-'설정'!$C$6),('설정'!$C$26*IF($A5>=31,1+'설정'!$C$14*'설정'!$E$26,1)/$D5)^(-'설정'!$C$7)),0)) | M5: =IF($E5*'설정'!$C$5*IF(('설정'!$C$27*IF($A5>=31,1+'설정'!$C$14*'설정'!$E$27,1)/$D5)<1,('설정'!$C$27*IF($A5>=31,1+'설정'!$C$14*'설정'!$E$27,1)/$D5)^(-'설정'!$C$6),('설정'!$C$27*IF($A5>=31,1+'설정'!$C$14*'설정'!$E$27,1)/$D5)^(-'설정'!$C$7))>('설정'!$C$4+'설정'!$F$27),"실패",ROUND($E5*'설정'!$C$5*IF(('설정'!$C$27*IF($A5>=31,1+'설정'!$C$14*'설정'!$E$27,1)/$D5)<1,('설정'!$C$27*IF($A5>=31,1+'설정'!$C$14*'설정'!$E$27,1)/$D5)^(-'설정'!$C$6),('설정'!$C$27*IF($A5>=31,1+'설정'!$C$14*'설정'!$E$27,1)/$D5)^(-'설정'!$C$7)),0)) | N5: =IF($E5*'설정'!$C$5*IF(('설정'!$C$28*IF($A5>=31,1+'설정'!$C$14*'설정'!$E$28,1)/$D5)<1,('설정'!$C$28*IF($A5>=31,1+'설정'!$C$14*'설정'!$E$28,1)/$D5)^(-'설정'!$C$6),('설정'!$C$28*IF($A5>=31,1+'설정'!$C$14*'설정'!$E$28,1)/$D5)^(-'설정'!$C$7))>('설정'!$C$4+'설정'!$F$28),"실패",ROUND($E5*'설정'!$C$5*IF(('설정'!$C$28*IF($A5>=31,1+'설정'!$C$14*'설정'!$E$28,1)/$D5)<1,('설정'!$C$28*IF($A5>=31,1+'설정'!$C$14*'설정'!$E$28,1)/$D5)^(-'설정'!$C$6),('설정'!$C$28*IF($A5>=31,1+'설정'!$C$14*'설정'!$E$28,1)/$D5)^(-'설정'!$C$7)),0)) | O5: =IF($E5*'설정'!$C$5*IF(('설정'!$C$29*IF($A5>=31,1+'설정'!$C$14*'설정'!$E$29,1)/$D5)<1,('설정'!$C$29*IF($A5>=31,1+'설정'!$C$14*'설정'!$E$29,1)/$D5)^(-'설정'!$C$6),('설정'!$C$29*IF($A5>=31,1+'설정'!$C$14*'설정'!$E$29,1)/$D5)^(-'설정'!$C$7))>('설정'!$C$4+'설정'!$F$29),"실패",ROUND($E5*'설정'!$C$5*IF(('설정'!$C$29*IF($A5>=31,1+'설정'!$C$14*'설정'!$E$29,1)/$D5)<1,('설정'!$C$29*IF($A5>=31,1+'설정'!$C$14*'설정'!$E$29,1)/$D5)^(-'설정'!$C$6),('설정'!$C$29*IF($A5>=31,1+'설정'!$C$14*'설정'!$E$29,1)/$D5)^(-'설정'!$C$7)),0)) | P5: =IF($E5*'설정'!$C$5*IF(('설정'!$C$30*IF($A5>=31,1+'설정'!$C$14*'설정'!$E$30,1)/$D5)<1,('설정'!$C$30*IF($A5>=31,1+'설정'!$C$14*'설정'!$E$30,1)/$D5)^(-'설정'!$C$6),('설정'!$C$30*IF($A5>=31,1+'설정'!$C$14*'설정'!$E$30,1)/$D5)^(-'설정'!$C$7))>('설정'!$C$4+'설정'!$F$30),"실패",ROUND($E5*'설정'!$C$5*IF(('설정'!$C$30*IF($A5>=31,1+'설정'!$C$14*'설정'!$E$30,1)/$D5)<1,('설정'!$C$30*IF($A5>=31,1+'설정'!$C$14*'설정'!$E$30,1)/$D5)^(-'설정'!$C$6),('설정'!$C$30*IF($A5>=31,1+'설정'!$C$14*'설정'!$E$30,1)/$D5)^(-'설정'!$C$7)),0)) | Q5: =IF($E5*'설정'!$C$5*IF(('설정'!$C$31*IF($A5>=31,1+'설정'!$C$14*'설정'!$E$31,1)/$D5)<1,('설정'!$C$31*IF($A5>=31,1+'설정'!$C$14*'설정'!$E$31,1)/$D5)^(-'설정'!$C$6),('설정'!$C$31*IF($A5>=31,1+'설정'!$C$14*'설정'!$E$31,1)/$D5)^(-'설정'!$C$7))>('설정'!$C$4+'설정'!$F$31),"실패",ROUND($E5*'설정'!$C$5*IF(('설정'!$C$31*IF($A5>=31,1+'설정'!$C$14*'설정'!$E$31,1)/$D5)<1,('설정'!$C$31*IF($A5>=31,1+'설정'!$C$14*'설정'!$E$31,1)/$D5)^(-'설정'!$C$6),('설정'!$C$31*IF($A5>=31,1+'설정'!$C$14*'설정'!$E$31,1)/$D5)^(-'설정'!$C$7)),0)) | R5: =IF($E5*'설정'!$C$5*IF(('설정'!$C$32*IF($A5>=31,1+'설정'!$C$14*'설정'!$E$32,1)/$D5)<1,('설정'!$C$32*IF($A5>=31,1+'설정'!$C$14*'설정'!$E$32,1)/$D5)^(-'설정'!$C$6),('설정'!$C$32*IF($A5>=31,1+'설정'!$C$14*'설정'!$E$32,1)/$D5)^(-'설정'!$C$7))>('설정'!$C$4+'설정'!$F$32),"실패",ROUND($E5*'설정'!$C$5*IF(('설정'!$C$32*IF($A5>=31,1+'설정'!$C$14*'설정'!$E$32,1)/$D5)<1,('설정'!$C$32*IF($A5>=31,1+'설정'!$C$14*'설정'!$E$32,1)/$D5)^(-'설정'!$C$6),('설정'!$C$32*IF($A5>=31,1+'설정'!$C$14*'설정'!$E$32,1)/$D5)^(-'설정'!$C$7)),0)) | S5: =IF($E5*'설정'!$C$5*IF(('설정'!$C$33*IF($A5>=31,1+'설정'!$C$14*'설정'!$E$33,1)/$D5)<1,('설정'!$C$33*IF($A5>=31,1+'설정'!$C$14*'설정'!$E$33,1)/$D5)^(-'설정'!$C$6),('설정'!$C$33*IF($A5>=31,1+'설정'!$C$14*'설정'!$E$33,1)/$D5)^(-'설정'!$C$7))>('설정'!$C$4+'설정'!$F$33),"실패",ROUND($E5*'설정'!$C$5*IF(('설정'!$C$33*IF($A5>=31,1+'설정'!$C$14*'설정'!$E$33,1)/$D5)<1,('설정'!$C$33*IF($A5>=31,1+'설정'!$C$14*'설정'!$E$33,1)/$D5)^(-'설정'!$C$6),('설정'!$C$33*IF($A5>=31,1+'설정'!$C$14*'설정'!$E$33,1)/$D5)^(-'설정'!$C$7)),0)) | T5: =IF($E5*'설정'!$C$5*IF(('설정'!$C$34*IF($A5>=31,1+'설정'!$C$14*'설정'!$E$34,1)/$D5)<1,('설정'!$C$34*IF($A5>=31,1+'설정'!$C$14*'설정'!$E$34,1)/$D5)^(-'설정'!$C$6),('설정'!$C$34*IF($A5>=31,1+'설정'!$C$14*'설정'!$E$34,1)/$D5)^(-'설정'!$C$7))>('설정'!$C$4+'설정'!$F$34),"실패",ROUND($E5*'설정'!$C$5*IF(('설정'!$C$34*IF($A5>=31,1+'설정'!$C$14*'설정'!$E$34,1)/$D5)<1,('설정'!$C$34*IF($A5>=31,1+'설정'!$C$14*'설정'!$E$34,1)/$D5)^(-'설정'!$C$6),('설정'!$C$34*IF($A5>=31,1+'설정'!$C$14*'설정'!$E$34,1)/$D5)^(-'설정'!$C$7)),0)) | U5: =IF($E5*'설정'!$C$5*IF(('설정'!$C$35*IF($A5>=31,1+'설정'!$C$14*'설정'!$E$35,1)/$D5)<1,('설정'!$C$35*IF($A5>=31,1+'설정'!$C$14*'설정'!$E$35,1)/$D5)^(-'설정'!$C$6),('설정'!$C$35*IF($A5>=31,1+'설정'!$C$14*'설정'!$E$35,1)/$D5)^(-'설정'!$C$7))>('설정'!$C$4+'설정'!$F$35),"실패",ROUND($E5*'설정'!$C$5*IF(('설정'!$C$35*IF($A5>=31,1+'설정'!$C$14*'설정'!$E$35,1)/$D5)<1,('설정'!$C$35*IF($A5>=31,1+'설정'!$C$14*'설정'!$E$35,1)/$D5)^(-'설정'!$C$6),('설정'!$C$35*IF($A5>=31,1+'설정'!$C$14*'설정'!$E$35,1)/$D5)^(-'설정'!$C$7)),0)) | V5: =IF($E5*'설정'!$C$5*IF(('설정'!$C$36*IF($A5>=31,1+'설정'!$C$14*'설정'!$E$36,1)/$D5)<1,('설정'!$C$36*IF($A5>=31,1+'설정'!$C$14*'설정'!$E$36,1)/$D5)^(-'설정'!$C$6),('설정'!$C$36*IF($A5>=31,1+'설정'!$C$14*'설정'!$E$36,1)/$D5)^(-'설정'!$C$7))>('설정'!$C$4+'설정'!$F$36),"실패",ROUND($E5*'설정'!$C$5*IF(('설정'!$C$36*IF($A5>=31,1+'설정'!$C$14*'설정'!$E$36,1)/$D5)<1,('설정'!$C$36*IF($A5>=31,1+'설정'!$C$14*'설정'!$E$36,1)/$D5)^(-'설정'!$C$6),('설정'!$C$36*IF($A5>=31,1+'설정'!$C$14*'설정'!$E$36,1)/$D5)^(-'설정'!$C$7)),0)) | W5: =IF($E5*'설정'!$C$5*IF(('설정'!$C$37*IF($A5>=31,1+'설정'!$C$14*'설정'!$E$37,1)/$D5)<1,('설정'!$C$37*IF($A5>=31,1+'설정'!$C$14*'설정'!$E$37,1)/$D5)^(-'설정'!$C$6),('설정'!$C$37*IF($A5>=31,1+'설정'!$C$14*'설정'!$E$37,1)/$D5)^(-'설정'!$C$7))>('설정'!$C$4+'설정'!$F$37),"실패",ROUND($E5*'설정'!$C$5*IF(('설정'!$C$37*IF($A5>=31,1+'설정'!$C$14*'설정'!$E$37,1)/$D5)<1,('설정'!$C$37*IF($A5>=31,1+'설정'!$C$14*'설정'!$E$37,1)/$D5)^(-'설정'!$C$6),('설정'!$C$37*IF($A5>=31,1+'설정'!$C$14*'설정'!$E$37,1)/$D5)^(-'설정'!$C$7)),0))
A6: 4 | B6: 쉬움 | D6: 781 | E6: 72 | F6: 15.62 | G6: 1 | H6: =IF($E6*'설정'!$C$5*IF(('설정'!$C$22*IF($A6>=31,1+'설정'!$C$14*'설정'!$E$22,1)/$D6)<1,('설정'!$C$22*IF($A6>=31,1+'설정'!$C$14*'설정'!$E$22,1)/$D6)^(-'설정'!$C$6),('설정'!$C$22*IF($A6>=31,1+'설정'!$C$14*'설정'!$E$22,1)/$D6)^(-'설정'!$C$7))>('설정'!$C$4+'설정'!$F$22),"실패",ROUND($E6*'설정'!$C$5*IF(('설정'!$C$22*IF($A6>=31,1+'설정'!$C$14*'설정'!$E$22,1)/$D6)<1,('설정'!$C$22*IF($A6>=31,1+'설정'!$C$14*'설정'!$E$22,1)/$D6)^(-'설정'!$C$6),('설정'!$C$22*IF($A6>=31,1+'설정'!$C$14*'설정'!$E$22,1)/$D6)^(-'설정'!$C$7)),0)) | I6: =IF($E6*'설정'!$C$5*IF(('설정'!$C$23*IF($A6>=31,1+'설정'!$C$14*'설정'!$E$23,1)/$D6)<1,('설정'!$C$23*IF($A6>=31,1+'설정'!$C$14*'설정'!$E$23,1)/$D6)^(-'설정'!$C$6),('설정'!$C$23*IF($A6>=31,1+'설정'!$C$14*'설정'!$E$23,1)/$D6)^(-'설정'!$C$7))>('설정'!$C$4+'설정'!$F$23),"실패",ROUND($E6*'설정'!$C$5*IF(('설정'!$C$23*IF($A6>=31,1+'설정'!$C$14*'설정'!$E$23,1)/$D6)<1,('설정'!$C$23*IF($A6>=31,1+'설정'!$C$14*'설정'!$E$23,1)/$D6)^(-'설정'!$C$6),('설정'!$C$23*IF($A6>=31,1+'설정'!$C$14*'설정'!$E$23,1)/$D6)^(-'설정'!$C$7)),0)) | J6: =IF($E6*'설정'!$C$5*IF(('설정'!$C$24*IF($A6>=31,1+'설정'!$C$14*'설정'!$E$24,1)/$D6)<1,('설정'!$C$24*IF($A6>=31,1+'설정'!$C$14*'설정'!$E$24,1)/$D6)^(-'설정'!$C$6),('설정'!$C$24*IF($A6>=31,1+'설정'!$C$14*'설정'!$E$24,1)/$D6)^(-'설정'!$C$7))>('설정'!$C$4+'설정'!$F$24),"실패",ROUND($E6*'설정'!$C$5*IF(('설정'!$C$24*IF($A6>=31,1+'설정'!$C$14*'설정'!$E$24,1)/$D6)<1,('설정'!$C$24*IF($A6>=31,1+'설정'!$C$14*'설정'!$E$24,1)/$D6)^(-'설정'!$C$6),('설정'!$C$24*IF($A6>=31,1+'설정'!$C$14*'설정'!$E$24,1)/$D6)^(-'설정'!$C$7)),0)) | K6: =IF($E6*'설정'!$C$5*IF(('설정'!$C$25*IF($A6>=31,1+'설정'!$C$14*'설정'!$E$25,1)/$D6)<1,('설정'!$C$25*IF($A6>=31,1+'설정'!$C$14*'설정'!$E$25,1)/$D6)^(-'설정'!$C$6),('설정'!$C$25*IF($A6>=31,1+'설정'!$C$14*'설정'!$E$25,1)/$D6)^(-'설정'!$C$7))>('설정'!$C$4+'설정'!$F$25),"실패",ROUND($E6*'설정'!$C$5*IF(('설정'!$C$25*IF($A6>=31,1+'설정'!$C$14*'설정'!$E$25,1)/$D6)<1,('설정'!$C$25*IF($A6>=31,1+'설정'!$C$14*'설정'!$E$25,1)/$D6)^(-'설정'!$C$6),('설정'!$C$25*IF($A6>=31,1+'설정'!$C$14*'설정'!$E$25,1)/$D6)^(-'설정'!$C$7)),0)) | L6: =IF($E6*'설정'!$C$5*IF(('설정'!$C$26*IF($A6>=31,1+'설정'!$C$14*'설정'!$E$26,1)/$D6)<1,('설정'!$C$26*IF($A6>=31,1+'설정'!$C$14*'설정'!$E$26,1)/$D6)^(-'설정'!$C$6),('설정'!$C$26*IF($A6>=31,1+'설정'!$C$14*'설정'!$E$26,1)/$D6)^(-'설정'!$C$7))>('설정'!$C$4+'설정'!$F$26),"실패",ROUND($E6*'설정'!$C$5*IF(('설정'!$C$26*IF($A6>=31,1+'설정'!$C$14*'설정'!$E$26,1)/$D6)<1,('설정'!$C$26*IF($A6>=31,1+'설정'!$C$14*'설정'!$E$26,1)/$D6)^(-'설정'!$C$6),('설정'!$C$26*IF($A6>=31,1+'설정'!$C$14*'설정'!$E$26,1)/$D6)^(-'설정'!$C$7)),0)) | M6: =IF($E6*'설정'!$C$5*IF(('설정'!$C$27*IF($A6>=31,1+'설정'!$C$14*'설정'!$E$27,1)/$D6)<1,('설정'!$C$27*IF($A6>=31,1+'설정'!$C$14*'설정'!$E$27,1)/$D6)^(-'설정'!$C$6),('설정'!$C$27*IF($A6>=31,1+'설정'!$C$14*'설정'!$E$27,1)/$D6)^(-'설정'!$C$7))>('설정'!$C$4+'설정'!$F$27),"실패",ROUND($E6*'설정'!$C$5*IF(('설정'!$C$27*IF($A6>=31,1+'설정'!$C$14*'설정'!$E$27,1)/$D6)<1,('설정'!$C$27*IF($A6>=31,1+'설정'!$C$14*'설정'!$E$27,1)/$D6)^(-'설정'!$C$6),('설정'!$C$27*IF($A6>=31,1+'설정'!$C$14*'설정'!$E$27,1)/$D6)^(-'설정'!$C$7)),0)) | N6: =IF($E6*'설정'!$C$5*IF(('설정'!$C$28*IF($A6>=31,1+'설정'!$C$14*'설정'!$E$28,1)/$D6)<1,('설정'!$C$28*IF($A6>=31,1+'설정'!$C$14*'설정'!$E$28,1)/$D6)^(-'설정'!$C$6),('설정'!$C$28*IF($A6>=31,1+'설정'!$C$14*'설정'!$E$28,1)/$D6)^(-'설정'!$C$7))>('설정'!$C$4+'설정'!$F$28),"실패",ROUND($E6*'설정'!$C$5*IF(('설정'!$C$28*IF($A6>=31,1+'설정'!$C$14*'설정'!$E$28,1)/$D6)<1,('설정'!$C$28*IF($A6>=31,1+'설정'!$C$14*'설정'!$E$28,1)/$D6)^(-'설정'!$C$6),('설정'!$C$28*IF($A6>=31,1+'설정'!$C$14*'설정'!$E$28,1)/$D6)^(-'설정'!$C$7)),0)) | O6: =IF($E6*'설정'!$C$5*IF(('설정'!$C$29*IF($A6>=31,1+'설정'!$C$14*'설정'!$E$29,1)/$D6)<1,('설정'!$C$29*IF($A6>=31,1+'설정'!$C$14*'설정'!$E$29,1)/$D6)^(-'설정'!$C$6),('설정'!$C$29*IF($A6>=31,1+'설정'!$C$14*'설정'!$E$29,1)/$D6)^(-'설정'!$C$7))>('설정'!$C$4+'설정'!$F$29),"실패",ROUND($E6*'설정'!$C$5*IF(('설정'!$C$29*IF($A6>=31,1+'설정'!$C$14*'설정'!$E$29,1)/$D6)<1,('설정'!$C$29*IF($A6>=31,1+'설정'!$C$14*'설정'!$E$29,1)/$D6)^(-'설정'!$C$6),('설정'!$C$29*IF($A6>=31,1+'설정'!$C$14*'설정'!$E$29,1)/$D6)^(-'설정'!$C$7)),0)) | P6: =IF($E6*'설정'!$C$5*IF(('설정'!$C$30*IF($A6>=31,1+'설정'!$C$14*'설정'!$E$30,1)/$D6)<1,('설정'!$C$30*IF($A6>=31,1+'설정'!$C$14*'설정'!$E$30,1)/$D6)^(-'설정'!$C$6),('설정'!$C$30*IF($A6>=31,1+'설정'!$C$14*'설정'!$E$30,1)/$D6)^(-'설정'!$C$7))>('설정'!$C$4+'설정'!$F$30),"실패",ROUND($E6*'설정'!$C$5*IF(('설정'!$C$30*IF($A6>=31,1+'설정'!$C$14*'설정'!$E$30,1)/$D6)<1,('설정'!$C$30*IF($A6>=31,1+'설정'!$C$14*'설정'!$E$30,1)/$D6)^(-'설정'!$C$6),('설정'!$C$30*IF($A6>=31,1+'설정'!$C$14*'설정'!$E$30,1)/$D6)^(-'설정'!$C$7)),0)) | Q6: =IF($E6*'설정'!$C$5*IF(('설정'!$C$31*IF($A6>=31,1+'설정'!$C$14*'설정'!$E$31,1)/$D6)<1,('설정'!$C$31*IF($A6>=31,1+'설정'!$C$14*'설정'!$E$31,1)/$D6)^(-'설정'!$C$6),('설정'!$C$31*IF($A6>=31,1+'설정'!$C$14*'설정'!$E$31,1)/$D6)^(-'설정'!$C$7))>('설정'!$C$4+'설정'!$F$31),"실패",ROUND($E6*'설정'!$C$5*IF(('설정'!$C$31*IF($A6>=31,1+'설정'!$C$14*'설정'!$E$31,1)/$D6)<1,('설정'!$C$31*IF($A6>=31,1+'설정'!$C$14*'설정'!$E$31,1)/$D6)^(-'설정'!$C$6),('설정'!$C$31*IF($A6>=31,1+'설정'!$C$14*'설정'!$E$31,1)/$D6)^(-'설정'!$C$7)),0)) | R6: =IF($E6*'설정'!$C$5*IF(('설정'!$C$32*IF($A6>=31,1+'설정'!$C$14*'설정'!$E$32,1)/$D6)<1,('설정'!$C$32*IF($A6>=31,1+'설정'!$C$14*'설정'!$E$32,1)/$D6)^(-'설정'!$C$6),('설정'!$C$32*IF($A6>=31,1+'설정'!$C$14*'설정'!$E$32,1)/$D6)^(-'설정'!$C$7))>('설정'!$C$4+'설정'!$F$32),"실패",ROUND($E6*'설정'!$C$5*IF(('설정'!$C$32*IF($A6>=31,1+'설정'!$C$14*'설정'!$E$32,1)/$D6)<1,('설정'!$C$32*IF($A6>=31,1+'설정'!$C$14*'설정'!$E$32,1)/$D6)^(-'설정'!$C$6),('설정'!$C$32*IF($A6>=31,1+'설정'!$C$14*'설정'!$E$32,1)/$D6)^(-'설정'!$C$7)),0)) | S6: =IF($E6*'설정'!$C$5*IF(('설정'!$C$33*IF($A6>=31,1+'설정'!$C$14*'설정'!$E$33,1)/$D6)<1,('설정'!$C$33*IF($A6>=31,1+'설정'!$C$14*'설정'!$E$33,1)/$D6)^(-'설정'!$C$6),('설정'!$C$33*IF($A6>=31,1+'설정'!$C$14*'설정'!$E$33,1)/$D6)^(-'설정'!$C$7))>('설정'!$C$4+'설정'!$F$33),"실패",ROUND($E6*'설정'!$C$5*IF(('설정'!$C$33*IF($A6>=31,1+'설정'!$C$14*'설정'!$E$33,1)/$D6)<1,('설정'!$C$33*IF($A6>=31,1+'설정'!$C$14*'설정'!$E$33,1)/$D6)^(-'설정'!$C$6),('설정'!$C$33*IF($A6>=31,1+'설정'!$C$14*'설정'!$E$33,1)/$D6)^(-'설정'!$C$7)),0)) | T6: =IF($E6*'설정'!$C$5*IF(('설정'!$C$34*IF($A6>=31,1+'설정'!$C$14*'설정'!$E$34,1)/$D6)<1,('설정'!$C$34*IF($A6>=31,1+'설정'!$C$14*'설정'!$E$34,1)/$D6)^(-'설정'!$C$6),('설정'!$C$34*IF($A6>=31,1+'설정'!$C$14*'설정'!$E$34,1)/$D6)^(-'설정'!$C$7))>('설정'!$C$4+'설정'!$F$34),"실패",ROUND($E6*'설정'!$C$5*IF(('설정'!$C$34*IF($A6>=31,1+'설정'!$C$14*'설정'!$E$34,1)/$D6)<1,('설정'!$C$34*IF($A6>=31,1+'설정'!$C$14*'설정'!$E$34,1)/$D6)^(-'설정'!$C$6),('설정'!$C$34*IF($A6>=31,1+'설정'!$C$14*'설정'!$E$34,1)/$D6)^(-'설정'!$C$7)),0)) | U6: =IF($E6*'설정'!$C$5*IF(('설정'!$C$35*IF($A6>=31,1+'설정'!$C$14*'설정'!$E$35,1)/$D6)<1,('설정'!$C$35*IF($A6>=31,1+'설정'!$C$14*'설정'!$E$35,1)/$D6)^(-'설정'!$C$6),('설정'!$C$35*IF($A6>=31,1+'설정'!$C$14*'설정'!$E$35,1)/$D6)^(-'설정'!$C$7))>('설정'!$C$4+'설정'!$F$35),"실패",ROUND($E6*'설정'!$C$5*IF(('설정'!$C$35*IF($A6>=31,1+'설정'!$C$14*'설정'!$E$35,1)/$D6)<1,('설정'!$C$35*IF($A6>=31,1+'설정'!$C$14*'설정'!$E$35,1)/$D6)^(-'설정'!$C$6),('설정'!$C$35*IF($A6>=31,1+'설정'!$C$14*'설정'!$E$35,1)/$D6)^(-'설정'!$C$7)),0)) | V6: =IF($E6*'설정'!$C$5*IF(('설정'!$C$36*IF($A6>=31,1+'설정'!$C$14*'설정'!$E$36,1)/$D6)<1,('설정'!$C$36*IF($A6>=31,1+'설정'!$C$14*'설정'!$E$36,1)/$D6)^(-'설정'!$C$6),('설정'!$C$36*IF($A6>=31,1+'설정'!$C$14*'설정'!$E$36,1)/$D6)^(-'설정'!$C$7))>('설정'!$C$4+'설정'!$F$36),"실패",ROUND($E6*'설정'!$C$5*IF(('설정'!$C$36*IF($A6>=31,1+'설정'!$C$14*'설정'!$E$36,1)/$D6)<1,('설정'!$C$36*IF($A6>=31,1+'설정'!$C$14*'설정'!$E$36,1)/$D6)^(-'설정'!$C$6),('설정'!$C$36*IF($A6>=31,1+'설정'!$C$14*'설정'!$E$36,1)/$D6)^(-'설정'!$C$7)),0)) | W6: =IF($E6*'설정'!$C$5*IF(('설정'!$C$37*IF($A6>=31,1+'설정'!$C$14*'설정'!$E$37,1)/$D6)<1,('설정'!$C$37*IF($A6>=31,1+'설정'!$C$14*'설정'!$E$37,1)/$D6)^(-'설정'!$C$6),('설정'!$C$37*IF($A6>=31,1+'설정'!$C$14*'설정'!$E$37,1)/$D6)^(-'설정'!$C$7))>('설정'!$C$4+'설정'!$F$37),"실패",ROUND($E6*'설정'!$C$5*IF(('설정'!$C$37*IF($A6>=31,1+'설정'!$C$14*'설정'!$E$37,1)/$D6)<1,('설정'!$C$37*IF($A6>=31,1+'설정'!$C$14*'설정'!$E$37,1)/$D6)^(-'설정'!$C$6),('설정'!$C$37*IF($A6>=31,1+'설정'!$C$14*'설정'!$E$37,1)/$D6)^(-'설정'!$C$7)),0))
A7: 5 | B7: 허들 | C7: 보스 | D7: 1410 | E7: 108 | F7: 28.12 | G7: 3 | H7: =IF($E7*'설정'!$C$5*IF(('설정'!$C$22*IF($A7>=31,1+'설정'!$C$14*'설정'!$E$22,1)/$D7)<1,('설정'!$C$22*IF($A7>=31,1+'설정'!$C$14*'설정'!$E$22,1)/$D7)^(-'설정'!$C$6),('설정'!$C$22*IF($A7>=31,1+'설정'!$C$14*'설정'!$E$22,1)/$D7)^(-'설정'!$C$7))>('설정'!$C$4+'설정'!$F$22+'설정'!$G$22),"실패",ROUND($E7*'설정'!$C$5*IF(('설정'!$C$22*IF($A7>=31,1+'설정'!$C$14*'설정'!$E$22,1)/$D7)<1,('설정'!$C$22*IF($A7>=31,1+'설정'!$C$14*'설정'!$E$22,1)/$D7)^(-'설정'!$C$6),('설정'!$C$22*IF($A7>=31,1+'설정'!$C$14*'설정'!$E$22,1)/$D7)^(-'설정'!$C$7)),0)) | I7: =IF($E7*'설정'!$C$5*IF(('설정'!$C$23*IF($A7>=31,1+'설정'!$C$14*'설정'!$E$23,1)/$D7)<1,('설정'!$C$23*IF($A7>=31,1+'설정'!$C$14*'설정'!$E$23,1)/$D7)^(-'설정'!$C$6),('설정'!$C$23*IF($A7>=31,1+'설정'!$C$14*'설정'!$E$23,1)/$D7)^(-'설정'!$C$7))>('설정'!$C$4+'설정'!$F$23+'설정'!$G$23),"실패",ROUND($E7*'설정'!$C$5*IF(('설정'!$C$23*IF($A7>=31,1+'설정'!$C$14*'설정'!$E$23,1)/$D7)<1,('설정'!$C$23*IF($A7>=31,1+'설정'!$C$14*'설정'!$E$23,1)/$D7)^(-'설정'!$C$6),('설정'!$C$23*IF($A7>=31,1+'설정'!$C$14*'설정'!$E$23,1)/$D7)^(-'설정'!$C$7)),0)) | J7: =IF($E7*'설정'!$C$5*IF(('설정'!$C$24*IF($A7>=31,1+'설정'!$C$14*'설정'!$E$24,1)/$D7)<1,('설정'!$C$24*IF($A7>=31,1+'설정'!$C$14*'설정'!$E$24,1)/$D7)^(-'설정'!$C$6),('설정'!$C$24*IF($A7>=31,1+'설정'!$C$14*'설정'!$E$24,1)/$D7)^(-'설정'!$C$7))>('설정'!$C$4+'설정'!$F$24+'설정'!$G$24),"실패",ROUND($E7*'설정'!$C$5*IF(('설정'!$C$24*IF($A7>=31,1+'설정'!$C$14*'설정'!$E$24,1)/$D7)<1,('설정'!$C$24*IF($A7>=31,1+'설정'!$C$14*'설정'!$E$24,1)/$D7)^(-'설정'!$C$6),('설정'!$C$24*IF($A7>=31,1+'설정'!$C$14*'설정'!$E$24,1)/$D7)^(-'설정'!$C$7)),0)) | K7: =IF($E7*'설정'!$C$5*IF(('설정'!$C$25*IF($A7>=31,1+'설정'!$C$14*'설정'!$E$25,1)/$D7)<1,('설정'!$C$25*IF($A7>=31,1+'설정'!$C$14*'설정'!$E$25,1)/$D7)^(-'설정'!$C$6),('설정'!$C$25*IF($A7>=31,1+'설정'!$C$14*'설정'!$E$25,1)/$D7)^(-'설정'!$C$7))>('설정'!$C$4+'설정'!$F$25+'설정'!$G$25),"실패",ROUND($E7*'설정'!$C$5*IF(('설정'!$C$25*IF($A7>=31,1+'설정'!$C$14*'설정'!$E$25,1)/$D7)<1,('설정'!$C$25*IF($A7>=31,1+'설정'!$C$14*'설정'!$E$25,1)/$D7)^(-'설정'!$C$6),('설정'!$C$25*IF($A7>=31,1+'설정'!$C$14*'설정'!$E$25,1)/$D7)^(-'설정'!$C$7)),0)) | L7: =IF($E7*'설정'!$C$5*IF(('설정'!$C$26*IF($A7>=31,1+'설정'!$C$14*'설정'!$E$26,1)/$D7)<1,('설정'!$C$26*IF($A7>=31,1+'설정'!$C$14*'설정'!$E$26,1)/$D7)^(-'설정'!$C$6),('설정'!$C$26*IF($A7>=31,1+'설정'!$C$14*'설정'!$E$26,1)/$D7)^(-'설정'!$C$7))>('설정'!$C$4+'설정'!$F$26+'설정'!$G$26),"실패",ROUND($E7*'설정'!$C$5*IF(('설정'!$C$26*IF($A7>=31,1+'설정'!$C$14*'설정'!$E$26,1)/$D7)<1,('설정'!$C$26*IF($A7>=31,1+'설정'!$C$14*'설정'!$E$26,1)/$D7)^(-'설정'!$C$6),('설정'!$C$26*IF($A7>=31,1+'설정'!$C$14*'설정'!$E$26,1)/$D7)^(-'설정'!$C$7)),0)) | M7: =IF($E7*'설정'!$C$5*IF(('설정'!$C$27*IF($A7>=31,1+'설정'!$C$14*'설정'!$E$27,1)/$D7)<1,('설정'!$C$27*IF($A7>=31,1+'설정'!$C$14*'설정'!$E$27,1)/$D7)^(-'설정'!$C$6),('설정'!$C$27*IF($A7>=31,1+'설정'!$C$14*'설정'!$E$27,1)/$D7)^(-'설정'!$C$7))>('설정'!$C$4+'설정'!$F$27+'설정'!$G$27),"실패",ROUND($E7*'설정'!$C$5*IF(('설정'!$C$27*IF($A7>=31,1+'설정'!$C$14*'설정'!$E$27,1)/$D7)<1,('설정'!$C$27*IF($A7>=31,1+'설정'!$C$14*'설정'!$E$27,1)/$D7)^(-'설정'!$C$6),('설정'!$C$27*IF($A7>=31,1+'설정'!$C$14*'설정'!$E$27,1)/$D7)^(-'설정'!$C$7)),0)) | N7: =IF($E7*'설정'!$C$5*IF(('설정'!$C$28*IF($A7>=31,1+'설정'!$C$14*'설정'!$E$28,1)/$D7)<1,('설정'!$C$28*IF($A7>=31,1+'설정'!$C$14*'설정'!$E$28,1)/$D7)^(-'설정'!$C$6),('설정'!$C$28*IF($A7>=31,1+'설정'!$C$14*'설정'!$E$28,1)/$D7)^(-'설정'!$C$7))>('설정'!$C$4+'설정'!$F$28+'설정'!$G$28),"실패",ROUND($E7*'설정'!$C$5*IF(('설정'!$C$28*IF($A7>=31,1+'설정'!$C$14*'설정'!$E$28,1)/$D7)<1,('설정'!$C$28*IF($A7>=31,1+'설정'!$C$14*'설정'!$E$28,1)/$D7)^(-'설정'!$C$6),('설정'!$C$28*IF($A7>=31,1+'설정'!$C$14*'설정'!$E$28,1)/$D7)^(-'설정'!$C$7)),0)) | O7: =IF($E7*'설정'!$C$5*IF(('설정'!$C$29*IF($A7>=31,1+'설정'!$C$14*'설정'!$E$29,1)/$D7)<1,('설정'!$C$29*IF($A7>=31,1+'설정'!$C$14*'설정'!$E$29,1)/$D7)^(-'설정'!$C$6),('설정'!$C$29*IF($A7>=31,1+'설정'!$C$14*'설정'!$E$29,1)/$D7)^(-'설정'!$C$7))>('설정'!$C$4+'설정'!$F$29+'설정'!$G$29),"실패",ROUND($E7*'설정'!$C$5*IF(('설정'!$C$29*IF($A7>=31,1+'설정'!$C$14*'설정'!$E$29,1)/$D7)<1,('설정'!$C$29*IF($A7>=31,1+'설정'!$C$14*'설정'!$E$29,1)/$D7)^(-'설정'!$C$6),('설정'!$C$29*IF($A7>=31,1+'설정'!$C$14*'설정'!$E$29,1)/$D7)^(-'설정'!$C$7)),0)) | P7: =IF($E7*'설정'!$C$5*IF(('설정'!$C$30*IF($A7>=31,1+'설정'!$C$14*'설정'!$E$30,1)/$D7)<1,('설정'!$C$30*IF($A7>=31,1+'설정'!$C$14*'설정'!$E$30,1)/$D7)^(-'설정'!$C$6),('설정'!$C$30*IF($A7>=31,1+'설정'!$C$14*'설정'!$E$30,1)/$D7)^(-'설정'!$C$7))>('설정'!$C$4+'설정'!$F$30+'설정'!$G$30),"실패",ROUND($E7*'설정'!$C$5*IF(('설정'!$C$30*IF($A7>=31,1+'설정'!$C$14*'설정'!$E$30,1)/$D7)<1,('설정'!$C$30*IF($A7>=31,1+'설정'!$C$14*'설정'!$E$30,1)/$D7)^(-'설정'!$C$6),('설정'!$C$30*IF($A7>=31,1+'설정'!$C$14*'설정'!$E$30,1)/$D7)^(-'설정'!$C$7)),0)) | Q7: =IF($E7*'설정'!$C$5*IF(('설정'!$C$31*IF($A7>=31,1+'설정'!$C$14*'설정'!$E$31,1)/$D7)<1,('설정'!$C$31*IF($A7>=31,1+'설정'!$C$14*'설정'!$E$31,1)/$D7)^(-'설정'!$C$6),('설정'!$C$31*IF($A7>=31,1+'설정'!$C$14*'설정'!$E$31,1)/$D7)^(-'설정'!$C$7))>('설정'!$C$4+'설정'!$F$31+'설정'!$G$31),"실패",ROUND($E7*'설정'!$C$5*IF(('설정'!$C$31*IF($A7>=31,1+'설정'!$C$14*'설정'!$E$31,1)/$D7)<1,('설정'!$C$31*IF($A7>=31,1+'설정'!$C$14*'설정'!$E$31,1)/$D7)^(-'설정'!$C$6),('설정'!$C$31*IF($A7>=31,1+'설정'!$C$14*'설정'!$E$31,1)/$D7)^(-'설정'!$C$7)),0)) | R7: =IF($E7*'설정'!$C$5*IF(('설정'!$C$32*IF($A7>=31,1+'설정'!$C$14*'설정'!$E$32,1)/$D7)<1,('설정'!$C$32*IF($A7>=31,1+'설정'!$C$14*'설정'!$E$32,1)/$D7)^(-'설정'!$C$6),('설정'!$C$32*IF($A7>=31,1+'설정'!$C$14*'설정'!$E$32,1)/$D7)^(-'설정'!$C$7))>('설정'!$C$4+'설정'!$F$32+'설정'!$G$32),"실패",ROUND($E7*'설정'!$C$5*IF(('설정'!$C$32*IF($A7>=31,1+'설정'!$C$14*'설정'!$E$32,1)/$D7)<1,('설정'!$C$32*IF($A7>=31,1+'설정'!$C$14*'설정'!$E$32,1)/$D7)^(-'설정'!$C$6),('설정'!$C$32*IF($A7>=31,1+'설정'!$C$14*'설정'!$E$32,1)/$D7)^(-'설정'!$C$7)),0)) | S7: =IF($E7*'설정'!$C$5*IF(('설정'!$C$33*IF($A7>=31,1+'설정'!$C$14*'설정'!$E$33,1)/$D7)<1,('설정'!$C$33*IF($A7>=31,1+'설정'!$C$14*'설정'!$E$33,1)/$D7)^(-'설정'!$C$6),('설정'!$C$33*IF($A7>=31,1+'설정'!$C$14*'설정'!$E$33,1)/$D7)^(-'설정'!$C$7))>('설정'!$C$4+'설정'!$F$33+'설정'!$G$33),"실패",ROUND($E7*'설정'!$C$5*IF(('설정'!$C$33*IF($A7>=31,1+'설정'!$C$14*'설정'!$E$33,1)/$D7)<1,('설정'!$C$33*IF($A7>=31,1+'설정'!$C$14*'설정'!$E$33,1)/$D7)^(-'설정'!$C$6),('설정'!$C$33*IF($A7>=31,1+'설정'!$C$14*'설정'!$E$33,1)/$D7)^(-'설정'!$C$7)),0)) | T7: =IF($E7*'설정'!$C$5*IF(('설정'!$C$34*IF($A7>=31,1+'설정'!$C$14*'설정'!$E$34,1)/$D7)<1,('설정'!$C$34*IF($A7>=31,1+'설정'!$C$14*'설정'!$E$34,1)/$D7)^(-'설정'!$C$6),('설정'!$C$34*IF($A7>=31,1+'설정'!$C$14*'설정'!$E$34,1)/$D7)^(-'설정'!$C$7))>('설정'!$C$4+'설정'!$F$34+'설정'!$G$34),"실패",ROUND($E7*'설정'!$C$5*IF(('설정'!$C$34*IF($A7>=31,1+'설정'!$C$14*'설정'!$E$34,1)/$D7)<1,('설정'!$C$34*IF($A7>=31,1+'설정'!$C$14*'설정'!$E$34,1)/$D7)^(-'설정'!$C$6),('설정'!$C$34*IF($A7>=31,1+'설정'!$C$14*'설정'!$E$34,1)/$D7)^(-'설정'!$C$7)),0)) | U7: =IF($E7*'설정'!$C$5*IF(('설정'!$C$35*IF($A7>=31,1+'설정'!$C$14*'설정'!$E$35,1)/$D7)<1,('설정'!$C$35*IF($A7>=31,1+'설정'!$C$14*'설정'!$E$35,1)/$D7)^(-'설정'!$C$6),('설정'!$C$35*IF($A7>=31,1+'설정'!$C$14*'설정'!$E$35,1)/$D7)^(-'설정'!$C$7))>('설정'!$C$4+'설정'!$F$35+'설정'!$G$35),"실패",ROUND($E7*'설정'!$C$5*IF(('설정'!$C$35*IF($A7>=31,1+'설정'!$C$14*'설정'!$E$35,1)/$D7)<1,('설정'!$C$35*IF($A7>=31,1+'설정'!$C$14*'설정'!$E$35,1)/$D7)^(-'설정'!$C$6),('설정'!$C$35*IF($A7>=31,1+'설정'!$C$14*'설정'!$E$35,1)/$D7)^(-'설정'!$C$7)),0)) | V7: =IF($E7*'설정'!$C$5*IF(('설정'!$C$36*IF($A7>=31,1+'설정'!$C$14*'설정'!$E$36,1)/$D7)<1,('설정'!$C$36*IF($A7>=31,1+'설정'!$C$14*'설정'!$E$36,1)/$D7)^(-'설정'!$C$6),('설정'!$C$36*IF($A7>=31,1+'설정'!$C$14*'설정'!$E$36,1)/$D7)^(-'설정'!$C$7))>('설정'!$C$4+'설정'!$F$36+'설정'!$G$36),"실패",ROUND($E7*'설정'!$C$5*IF(('설정'!$C$36*IF($A7>=31,1+'설정'!$C$14*'설정'!$E$36,1)/$D7)<1,('설정'!$C$36*IF($A7>=31,1+'설정'!$C$14*'설정'!$E$36,1)/$D7)^(-'설정'!$C$6),('설정'!$C$36*IF($A7>=31,1+'설정'!$C$14*'설정'!$E$36,1)/$D7)^(-'설정'!$C$7)),0)) | W7: =IF($E7*'설정'!$C$5*IF(('설정'!$C$37*IF($A7>=31,1+'설정'!$C$14*'설정'!$E$37,1)/$D7)<1,('설정'!$C$37*IF($A7>=31,1+'설정'!$C$14*'설정'!$E$37,1)/$D7)^(-'설정'!$C$6),('설정'!$C$37*IF($A7>=31,1+'설정'!$C$14*'설정'!$E$37,1)/$D7)^(-'설정'!$C$7))>('설정'!$C$4+'설정'!$F$37+'설정'!$G$37),"실패",ROUND($E7*'설정'!$C$5*IF(('설정'!$C$37*IF($A7>=31,1+'설정'!$C$14*'설정'!$E$37,1)/$D7)<1,('설정'!$C$37*IF($A7>=31,1+'설정'!$C$14*'설정'!$E$37,1)/$D7)^(-'설정'!$C$6),('설정'!$C$37*IF($A7>=31,1+'설정'!$C$14*'설정'!$E$37,1)/$D7)^(-'설정'!$C$7)),0))
A8: 6 | B8: 보통 | D8: 1860 | E8: 72 | F8: 37.12 | G8: 4 | H8: =IF($E8*'설정'!$C$5*IF(('설정'!$C$22*IF($A8>=31,1+'설정'!$C$14*'설정'!$E$22,1)/$D8)<1,('설정'!$C$22*IF($A8>=31,1+'설정'!$C$14*'설정'!$E$22,1)/$D8)^(-'설정'!$C$6),('설정'!$C$22*IF($A8>=31,1+'설정'!$C$14*'설정'!$E$22,1)/$D8)^(-'설정'!$C$7))>('설정'!$C$4+'설정'!$F$22),"실패",ROUND($E8*'설정'!$C$5*IF(('설정'!$C$22*IF($A8>=31,1+'설정'!$C$14*'설정'!$E$22,1)/$D8)<1,('설정'!$C$22*IF($A8>=31,1+'설정'!$C$14*'설정'!$E$22,1)/$D8)^(-'설정'!$C$6),('설정'!$C$22*IF($A8>=31,1+'설정'!$C$14*'설정'!$E$22,1)/$D8)^(-'설정'!$C$7)),0)) | I8: =IF($E8*'설정'!$C$5*IF(('설정'!$C$23*IF($A8>=31,1+'설정'!$C$14*'설정'!$E$23,1)/$D8)<1,('설정'!$C$23*IF($A8>=31,1+'설정'!$C$14*'설정'!$E$23,1)/$D8)^(-'설정'!$C$6),('설정'!$C$23*IF($A8>=31,1+'설정'!$C$14*'설정'!$E$23,1)/$D8)^(-'설정'!$C$7))>('설정'!$C$4+'설정'!$F$23),"실패",ROUND($E8*'설정'!$C$5*IF(('설정'!$C$23*IF($A8>=31,1+'설정'!$C$14*'설정'!$E$23,1)/$D8)<1,('설정'!$C$23*IF($A8>=31,1+'설정'!$C$14*'설정'!$E$23,1)/$D8)^(-'설정'!$C$6),('설정'!$C$23*IF($A8>=31,1+'설정'!$C$14*'설정'!$E$23,1)/$D8)^(-'설정'!$C$7)),0)) | J8: =IF($E8*'설정'!$C$5*IF(('설정'!$C$24*IF($A8>=31,1+'설정'!$C$14*'설정'!$E$24,1)/$D8)<1,('설정'!$C$24*IF($A8>=31,1+'설정'!$C$14*'설정'!$E$24,1)/$D8)^(-'설정'!$C$6),('설정'!$C$24*IF($A8>=31,1+'설정'!$C$14*'설정'!$E$24,1)/$D8)^(-'설정'!$C$7))>('설정'!$C$4+'설정'!$F$24),"실패",ROUND($E8*'설정'!$C$5*IF(('설정'!$C$24*IF($A8>=31,1+'설정'!$C$14*'설정'!$E$24,1)/$D8)<1,('설정'!$C$24*IF($A8>=31,1+'설정'!$C$14*'설정'!$E$24,1)/$D8)^(-'설정'!$C$6),('설정'!$C$24*IF($A8>=31,1+'설정'!$C$14*'설정'!$E$24,1)/$D8)^(-'설정'!$C$7)),0)) | K8: =IF($E8*'설정'!$C$5*IF(('설정'!$C$25*IF($A8>=31,1+'설정'!$C$14*'설정'!$E$25,1)/$D8)<1,('설정'!$C$25*IF($A8>=31,1+'설정'!$C$14*'설정'!$E$25,1)/$D8)^(-'설정'!$C$6),('설정'!$C$25*IF($A8>=31,1+'설정'!$C$14*'설정'!$E$25,1)/$D8)^(-'설정'!$C$7))>('설정'!$C$4+'설정'!$F$25),"실패",ROUND($E8*'설정'!$C$5*IF(('설정'!$C$25*IF($A8>=31,1+'설정'!$C$14*'설정'!$E$25,1)/$D8)<1,('설정'!$C$25*IF($A8>=31,1+'설정'!$C$14*'설정'!$E$25,1)/$D8)^(-'설정'!$C$6),('설정'!$C$25*IF($A8>=31,1+'설정'!$C$14*'설정'!$E$25,1)/$D8)^(-'설정'!$C$7)),0)) | L8: =IF($E8*'설정'!$C$5*IF(('설정'!$C$26*IF($A8>=31,1+'설정'!$C$14*'설정'!$E$26,1)/$D8)<1,('설정'!$C$26*IF($A8>=31,1+'설정'!$C$14*'설정'!$E$26,1)/$D8)^(-'설정'!$C$6),('설정'!$C$26*IF($A8>=31,1+'설정'!$C$14*'설정'!$E$26,1)/$D8)^(-'설정'!$C$7))>('설정'!$C$4+'설정'!$F$26),"실패",ROUND($E8*'설정'!$C$5*IF(('설정'!$C$26*IF($A8>=31,1+'설정'!$C$14*'설정'!$E$26,1)/$D8)<1,('설정'!$C$26*IF($A8>=31,1+'설정'!$C$14*'설정'!$E$26,1)/$D8)^(-'설정'!$C$6),('설정'!$C$26*IF($A8>=31,1+'설정'!$C$14*'설정'!$E$26,1)/$D8)^(-'설정'!$C$7)),0)) | M8: =IF($E8*'설정'!$C$5*IF(('설정'!$C$27*IF($A8>=31,1+'설정'!$C$14*'설정'!$E$27,1)/$D8)<1,('설정'!$C$27*IF($A8>=31,1+'설정'!$C$14*'설정'!$E$27,1)/$D8)^(-'설정'!$C$6),('설정'!$C$27*IF($A8>=31,1+'설정'!$C$14*'설정'!$E$27,1)/$D8)^(-'설정'!$C$7))>('설정'!$C$4+'설정'!$F$27),"실패",ROUND($E8*'설정'!$C$5*IF(('설정'!$C$27*IF($A8>=31,1+'설정'!$C$14*'설정'!$E$27,1)/$D8)<1,('설정'!$C$27*IF($A8>=31,1+'설정'!$C$14*'설정'!$E$27,1)/$D8)^(-'설정'!$C$6),('설정'!$C$27*IF($A8>=31,1+'설정'!$C$14*'설정'!$E$27,1)/$D8)^(-'설정'!$C$7)),0)) | N8: =IF($E8*'설정'!$C$5*IF(('설정'!$C$28*IF($A8>=31,1+'설정'!$C$14*'설정'!$E$28,1)/$D8)<1,('설정'!$C$28*IF($A8>=31,1+'설정'!$C$14*'설정'!$E$28,1)/$D8)^(-'설정'!$C$6),('설정'!$C$28*IF($A8>=31,1+'설정'!$C$14*'설정'!$E$28,1)/$D8)^(-'설정'!$C$7))>('설정'!$C$4+'설정'!$F$28),"실패",ROUND($E8*'설정'!$C$5*IF(('설정'!$C$28*IF($A8>=31,1+'설정'!$C$14*'설정'!$E$28,1)/$D8)<1,('설정'!$C$28*IF($A8>=31,1+'설정'!$C$14*'설정'!$E$28,1)/$D8)^(-'설정'!$C$6),('설정'!$C$28*IF($A8>=31,1+'설정'!$C$14*'설정'!$E$28,1)/$D8)^(-'설정'!$C$7)),0)) | O8: =IF($E8*'설정'!$C$5*IF(('설정'!$C$29*IF($A8>=31,1+'설정'!$C$14*'설정'!$E$29,1)/$D8)<1,('설정'!$C$29*IF($A8>=31,1+'설정'!$C$14*'설정'!$E$29,1)/$D8)^(-'설정'!$C$6),('설정'!$C$29*IF($A8>=31,1+'설정'!$C$14*'설정'!$E$29,1)/$D8)^(-'설정'!$C$7))>('설정'!$C$4+'설정'!$F$29),"실패",ROUND($E8*'설정'!$C$5*IF(('설정'!$C$29*IF($A8>=31,1+'설정'!$C$14*'설정'!$E$29,1)/$D8)<1,('설정'!$C$29*IF($A8>=31,1+'설정'!$C$14*'설정'!$E$29,1)/$D8)^(-'설정'!$C$6),('설정'!$C$29*IF($A8>=31,1+'설정'!$C$14*'설정'!$E$29,1)/$D8)^(-'설정'!$C$7)),0)) | P8: =IF($E8*'설정'!$C$5*IF(('설정'!$C$30*IF($A8>=31,1+'설정'!$C$14*'설정'!$E$30,1)/$D8)<1,('설정'!$C$30*IF($A8>=31,1+'설정'!$C$14*'설정'!$E$30,1)/$D8)^(-'설정'!$C$6),('설정'!$C$30*IF($A8>=31,1+'설정'!$C$14*'설정'!$E$30,1)/$D8)^(-'설정'!$C$7))>('설정'!$C$4+'설정'!$F$30),"실패",ROUND($E8*'설정'!$C$5*IF(('설정'!$C$30*IF($A8>=31,1+'설정'!$C$14*'설정'!$E$30,1)/$D8)<1,('설정'!$C$30*IF($A8>=31,1+'설정'!$C$14*'설정'!$E$30,1)/$D8)^(-'설정'!$C$6),('설정'!$C$30*IF($A8>=31,1+'설정'!$C$14*'설정'!$E$30,1)/$D8)^(-'설정'!$C$7)),0)) | Q8: =IF($E8*'설정'!$C$5*IF(('설정'!$C$31*IF($A8>=31,1+'설정'!$C$14*'설정'!$E$31,1)/$D8)<1,('설정'!$C$31*IF($A8>=31,1+'설정'!$C$14*'설정'!$E$31,1)/$D8)^(-'설정'!$C$6),('설정'!$C$31*IF($A8>=31,1+'설정'!$C$14*'설정'!$E$31,1)/$D8)^(-'설정'!$C$7))>('설정'!$C$4+'설정'!$F$31),"실패",ROUND($E8*'설정'!$C$5*IF(('설정'!$C$31*IF($A8>=31,1+'설정'!$C$14*'설정'!$E$31,1)/$D8)<1,('설정'!$C$31*IF($A8>=31,1+'설정'!$C$14*'설정'!$E$31,1)/$D8)^(-'설정'!$C$6),('설정'!$C$31*IF($A8>=31,1+'설정'!$C$14*'설정'!$E$31,1)/$D8)^(-'설정'!$C$7)),0)) | R8: =IF($E8*'설정'!$C$5*IF(('설정'!$C$32*IF($A8>=31,1+'설정'!$C$14*'설정'!$E$32,1)/$D8)<1,('설정'!$C$32*IF($A8>=31,1+'설정'!$C$14*'설정'!$E$32,1)/$D8)^(-'설정'!$C$6),('설정'!$C$32*IF($A8>=31,1+'설정'!$C$14*'설정'!$E$32,1)/$D8)^(-'설정'!$C$7))>('설정'!$C$4+'설정'!$F$32),"실패",ROUND($E8*'설정'!$C$5*IF(('설정'!$C$32*IF($A8>=31,1+'설정'!$C$14*'설정'!$E$32,1)/$D8)<1,('설정'!$C$32*IF($A8>=31,1+'설정'!$C$14*'설정'!$E$32,1)/$D8)^(-'설정'!$C$6),('설정'!$C$32*IF($A8>=31,1+'설정'!$C$14*'설정'!$E$32,1)/$D8)^(-'설정'!$C$7)),0)) | S8: =IF($E8*'설정'!$C$5*IF(('설정'!$C$33*IF($A8>=31,1+'설정'!$C$14*'설정'!$E$33,1)/$D8)<1,('설정'!$C$33*IF($A8>=31,1+'설정'!$C$14*'설정'!$E$33,1)/$D8)^(-'설정'!$C$6),('설정'!$C$33*IF($A8>=31,1+'설정'!$C$14*'설정'!$E$33,1)/$D8)^(-'설정'!$C$7))>('설정'!$C$4+'설정'!$F$33),"실패",ROUND($E8*'설정'!$C$5*IF(('설정'!$C$33*IF($A8>=31,1+'설정'!$C$14*'설정'!$E$33,1)/$D8)<1,('설정'!$C$33*IF($A8>=31,1+'설정'!$C$14*'설정'!$E$33,1)/$D8)^(-'설정'!$C$6),('설정'!$C$33*IF($A8>=31,1+'설정'!$C$14*'설정'!$E$33,1)/$D8)^(-'설정'!$C$7)),0)) | T8: =IF($E8*'설정'!$C$5*IF(('설정'!$C$34*IF($A8>=31,1+'설정'!$C$14*'설정'!$E$34,1)/$D8)<1,('설정'!$C$34*IF($A8>=31,1+'설정'!$C$14*'설정'!$E$34,1)/$D8)^(-'설정'!$C$6),('설정'!$C$34*IF($A8>=31,1+'설정'!$C$14*'설정'!$E$34,1)/$D8)^(-'설정'!$C$7))>('설정'!$C$4+'설정'!$F$34),"실패",ROUND($E8*'설정'!$C$5*IF(('설정'!$C$34*IF($A8>=31,1+'설정'!$C$14*'설정'!$E$34,1)/$D8)<1,('설정'!$C$34*IF($A8>=31,1+'설정'!$C$14*'설정'!$E$34,1)/$D8)^(-'설정'!$C$6),('설정'!$C$34*IF($A8>=31,1+'설정'!$C$14*'설정'!$E$34,1)/$D8)^(-'설정'!$C$7)),0)) | U8: =IF($E8*'설정'!$C$5*IF(('설정'!$C$35*IF($A8>=31,1+'설정'!$C$14*'설정'!$E$35,1)/$D8)<1,('설정'!$C$35*IF($A8>=31,1+'설정'!$C$14*'설정'!$E$35,1)/$D8)^(-'설정'!$C$6),('설정'!$C$35*IF($A8>=31,1+'설정'!$C$14*'설정'!$E$35,1)/$D8)^(-'설정'!$C$7))>('설정'!$C$4+'설정'!$F$35),"실패",ROUND($E8*'설정'!$C$5*IF(('설정'!$C$35*IF($A8>=31,1+'설정'!$C$14*'설정'!$E$35,1)/$D8)<1,('설정'!$C$35*IF($A8>=31,1+'설정'!$C$14*'설정'!$E$35,1)/$D8)^(-'설정'!$C$6),('설정'!$C$35*IF($A8>=31,1+'설정'!$C$14*'설정'!$E$35,1)/$D8)^(-'설정'!$C$7)),0)) | V8: =IF($E8*'설정'!$C$5*IF(('설정'!$C$36*IF($A8>=31,1+'설정'!$C$14*'설정'!$E$36,1)/$D8)<1,('설정'!$C$36*IF($A8>=31,1+'설정'!$C$14*'설정'!$E$36,1)/$D8)^(-'설정'!$C$6),('설정'!$C$36*IF($A8>=31,1+'설정'!$C$14*'설정'!$E$36,1)/$D8)^(-'설정'!$C$7))>('설정'!$C$4+'설정'!$F$36),"실패",ROUND($E8*'설정'!$C$5*IF(('설정'!$C$36*IF($A8>=31,1+'설정'!$C$14*'설정'!$E$36,1)/$D8)<1,('설정'!$C$36*IF($A8>=31,1+'설정'!$C$14*'설정'!$E$36,1)/$D8)^(-'설정'!$C$6),('설정'!$C$36*IF($A8>=31,1+'설정'!$C$14*'설정'!$E$36,1)/$D8)^(-'설정'!$C$7)),0)) | W8: =IF($E8*'설정'!$C$5*IF(('설정'!$C$37*IF($A8>=31,1+'설정'!$C$14*'설정'!$E$37,1)/$D8)<1,('설정'!$C$37*IF($A8>=31,1+'설정'!$C$14*'설정'!$E$37,1)/$D8)^(-'설정'!$C$6),('설정'!$C$37*IF($A8>=31,1+'설정'!$C$14*'설정'!$E$37,1)/$D8)^(-'설정'!$C$7))>('설정'!$C$4+'설정'!$F$37),"실패",ROUND($E8*'설정'!$C$5*IF(('설정'!$C$37*IF($A8>=31,1+'설정'!$C$14*'설정'!$E$37,1)/$D8)<1,('설정'!$C$37*IF($A8>=31,1+'설정'!$C$14*'설정'!$E$37,1)/$D8)^(-'설정'!$C$6),('설정'!$C$37*IF($A8>=31,1+'설정'!$C$14*'설정'!$E$37,1)/$D8)^(-'설정'!$C$7)),0))
A9: 7 | B9: 보통 | D9: 2450 | E9: 72 | F9: 49.01 | G9: 4 | H9: =IF($E9*'설정'!$C$5*IF(('설정'!$C$22*IF($A9>=31,1+'설정'!$C$14*'설정'!$E$22,1)/$D9)<1,('설정'!$C$22*IF($A9>=31,1+'설정'!$C$14*'설정'!$E$22,1)/$D9)^(-'설정'!$C$6),('설정'!$C$22*IF($A9>=31,1+'설정'!$C$14*'설정'!$E$22,1)/$D9)^(-'설정'!$C$7))>('설정'!$C$4+'설정'!$F$22),"실패",ROUND($E9*'설정'!$C$5*IF(('설정'!$C$22*IF($A9>=31,1+'설정'!$C$14*'설정'!$E$22,1)/$D9)<1,('설정'!$C$22*IF($A9>=31,1+'설정'!$C$14*'설정'!$E$22,1)/$D9)^(-'설정'!$C$6),('설정'!$C$22*IF($A9>=31,1+'설정'!$C$14*'설정'!$E$22,1)/$D9)^(-'설정'!$C$7)),0)) | I9: =IF($E9*'설정'!$C$5*IF(('설정'!$C$23*IF($A9>=31,1+'설정'!$C$14*'설정'!$E$23,1)/$D9)<1,('설정'!$C$23*IF($A9>=31,1+'설정'!$C$14*'설정'!$E$23,1)/$D9)^(-'설정'!$C$6),('설정'!$C$23*IF($A9>=31,1+'설정'!$C$14*'설정'!$E$23,1)/$D9)^(-'설정'!$C$7))>('설정'!$C$4+'설정'!$F$23),"실패",ROUND($E9*'설정'!$C$5*IF(('설정'!$C$23*IF($A9>=31,1+'설정'!$C$14*'설정'!$E$23,1)/$D9)<1,('설정'!$C$23*IF($A9>=31,1+'설정'!$C$14*'설정'!$E$23,1)/$D9)^(-'설정'!$C$6),('설정'!$C$23*IF($A9>=31,1+'설정'!$C$14*'설정'!$E$23,1)/$D9)^(-'설정'!$C$7)),0)) | J9: =IF($E9*'설정'!$C$5*IF(('설정'!$C$24*IF($A9>=31,1+'설정'!$C$14*'설정'!$E$24,1)/$D9)<1,('설정'!$C$24*IF($A9>=31,1+'설정'!$C$14*'설정'!$E$24,1)/$D9)^(-'설정'!$C$6),('설정'!$C$24*IF($A9>=31,1+'설정'!$C$14*'설정'!$E$24,1)/$D9)^(-'설정'!$C$7))>('설정'!$C$4+'설정'!$F$24),"실패",ROUND($E9*'설정'!$C$5*IF(('설정'!$C$24*IF($A9>=31,1+'설정'!$C$14*'설정'!$E$24,1)/$D9)<1,('설정'!$C$24*IF($A9>=31,1+'설정'!$C$14*'설정'!$E$24,1)/$D9)^(-'설정'!$C$6),('설정'!$C$24*IF($A9>=31,1+'설정'!$C$14*'설정'!$E$24,1)/$D9)^(-'설정'!$C$7)),0)) | K9: =IF($E9*'설정'!$C$5*IF(('설정'!$C$25*IF($A9>=31,1+'설정'!$C$14*'설정'!$E$25,1)/$D9)<1,('설정'!$C$25*IF($A9>=31,1+'설정'!$C$14*'설정'!$E$25,1)/$D9)^(-'설정'!$C$6),('설정'!$C$25*IF($A9>=31,1+'설정'!$C$14*'설정'!$E$25,1)/$D9)^(-'설정'!$C$7))>('설정'!$C$4+'설정'!$F$25),"실패",ROUND($E9*'설정'!$C$5*IF(('설정'!$C$25*IF($A9>=31,1+'설정'!$C$14*'설정'!$E$25,1)/$D9)<1,('설정'!$C$25*IF($A9>=31,1+'설정'!$C$14*'설정'!$E$25,1)/$D9)^(-'설정'!$C$6),('설정'!$C$25*IF($A9>=31,1+'설정'!$C$14*'설정'!$E$25,1)/$D9)^(-'설정'!$C$7)),0)) | L9: =IF($E9*'설정'!$C$5*IF(('설정'!$C$26*IF($A9>=31,1+'설정'!$C$14*'설정'!$E$26,1)/$D9)<1,('설정'!$C$26*IF($A9>=31,1+'설정'!$C$14*'설정'!$E$26,1)/$D9)^(-'설정'!$C$6),('설정'!$C$26*IF($A9>=31,1+'설정'!$C$14*'설정'!$E$26,1)/$D9)^(-'설정'!$C$7))>('설정'!$C$4+'설정'!$F$26),"실패",ROUND($E9*'설정'!$C$5*IF(('설정'!$C$26*IF($A9>=31,1+'설정'!$C$14*'설정'!$E$26,1)/$D9)<1,('설정'!$C$26*IF($A9>=31,1+'설정'!$C$14*'설정'!$E$26,1)/$D9)^(-'설정'!$C$6),('설정'!$C$26*IF($A9>=31,1+'설정'!$C$14*'설정'!$E$26,1)/$D9)^(-'설정'!$C$7)),0)) | M9: =IF($E9*'설정'!$C$5*IF(('설정'!$C$27*IF($A9>=31,1+'설정'!$C$14*'설정'!$E$27,1)/$D9)<1,('설정'!$C$27*IF($A9>=31,1+'설정'!$C$14*'설정'!$E$27,1)/$D9)^(-'설정'!$C$6),('설정'!$C$27*IF($A9>=31,1+'설정'!$C$14*'설정'!$E$27,1)/$D9)^(-'설정'!$C$7))>('설정'!$C$4+'설정'!$F$27),"실패",ROUND($E9*'설정'!$C$5*IF(('설정'!$C$27*IF($A9>=31,1+'설정'!$C$14*'설정'!$E$27,1)/$D9)<1,('설정'!$C$27*IF($A9>=31,1+'설정'!$C$14*'설정'!$E$27,1)/$D9)^(-'설정'!$C$6),('설정'!$C$27*IF($A9>=31,1+'설정'!$C$14*'설정'!$E$27,1)/$D9)^(-'설정'!$C$7)),0)) | N9: =IF($E9*'설정'!$C$5*IF(('설정'!$C$28*IF($A9>=31,1+'설정'!$C$14*'설정'!$E$28,1)/$D9)<1,('설정'!$C$28*IF($A9>=31,1+'설정'!$C$14*'설정'!$E$28,1)/$D9)^(-'설정'!$C$6),('설정'!$C$28*IF($A9>=31,1+'설정'!$C$14*'설정'!$E$28,1)/$D9)^(-'설정'!$C$7))>('설정'!$C$4+'설정'!$F$28),"실패",ROUND($E9*'설정'!$C$5*IF(('설정'!$C$28*IF($A9>=31,1+'설정'!$C$14*'설정'!$E$28,1)/$D9)<1,('설정'!$C$28*IF($A9>=31,1+'설정'!$C$14*'설정'!$E$28,1)/$D9)^(-'설정'!$C$6),('설정'!$C$28*IF($A9>=31,1+'설정'!$C$14*'설정'!$E$28,1)/$D9)^(-'설정'!$C$7)),0)) | O9: =IF($E9*'설정'!$C$5*IF(('설정'!$C$29*IF($A9>=31,1+'설정'!$C$14*'설정'!$E$29,1)/$D9)<1,('설정'!$C$29*IF($A9>=31,1+'설정'!$C$14*'설정'!$E$29,1)/$D9)^(-'설정'!$C$6),('설정'!$C$29*IF($A9>=31,1+'설정'!$C$14*'설정'!$E$29,1)/$D9)^(-'설정'!$C$7))>('설정'!$C$4+'설정'!$F$29),"실패",ROUND($E9*'설정'!$C$5*IF(('설정'!$C$29*IF($A9>=31,1+'설정'!$C$14*'설정'!$E$29,1)/$D9)<1,('설정'!$C$29*IF($A9>=31,1+'설정'!$C$14*'설정'!$E$29,1)/$D9)^(-'설정'!$C$6),('설정'!$C$29*IF($A9>=31,1+'설정'!$C$14*'설정'!$E$29,1)/$D9)^(-'설정'!$C$7)),0)) | P9: =IF($E9*'설정'!$C$5*IF(('설정'!$C$30*IF($A9>=31,1+'설정'!$C$14*'설정'!$E$30,1)/$D9)<1,('설정'!$C$30*IF($A9>=31,1+'설정'!$C$14*'설정'!$E$30,1)/$D9)^(-'설정'!$C$6),('설정'!$C$30*IF($A9>=31,1+'설정'!$C$14*'설정'!$E$30,1)/$D9)^(-'설정'!$C$7))>('설정'!$C$4+'설정'!$F$30),"실패",ROUND($E9*'설정'!$C$5*IF(('설정'!$C$30*IF($A9>=31,1+'설정'!$C$14*'설정'!$E$30,1)/$D9)<1,('설정'!$C$30*IF($A9>=31,1+'설정'!$C$14*'설정'!$E$30,1)/$D9)^(-'설정'!$C$6),('설정'!$C$30*IF($A9>=31,1+'설정'!$C$14*'설정'!$E$30,1)/$D9)^(-'설정'!$C$7)),0)) | Q9: =IF($E9*'설정'!$C$5*IF(('설정'!$C$31*IF($A9>=31,1+'설정'!$C$14*'설정'!$E$31,1)/$D9)<1,('설정'!$C$31*IF($A9>=31,1+'설정'!$C$14*'설정'!$E$31,1)/$D9)^(-'설정'!$C$6),('설정'!$C$31*IF($A9>=31,1+'설정'!$C$14*'설정'!$E$31,1)/$D9)^(-'설정'!$C$7))>('설정'!$C$4+'설정'!$F$31),"실패",ROUND($E9*'설정'!$C$5*IF(('설정'!$C$31*IF($A9>=31,1+'설정'!$C$14*'설정'!$E$31,1)/$D9)<1,('설정'!$C$31*IF($A9>=31,1+'설정'!$C$14*'설정'!$E$31,1)/$D9)^(-'설정'!$C$6),('설정'!$C$31*IF($A9>=31,1+'설정'!$C$14*'설정'!$E$31,1)/$D9)^(-'설정'!$C$7)),0)) | R9: =IF($E9*'설정'!$C$5*IF(('설정'!$C$32*IF($A9>=31,1+'설정'!$C$14*'설정'!$E$32,1)/$D9)<1,('설정'!$C$32*IF($A9>=31,1+'설정'!$C$14*'설정'!$E$32,1)/$D9)^(-'설정'!$C$6),('설정'!$C$32*IF($A9>=31,1+'설정'!$C$14*'설정'!$E$32,1)/$D9)^(-'설정'!$C$7))>('설정'!$C$4+'설정'!$F$32),"실패",ROUND($E9*'설정'!$C$5*IF(('설정'!$C$32*IF($A9>=31,1+'설정'!$C$14*'설정'!$E$32,1)/$D9)<1,('설정'!$C$32*IF($A9>=31,1+'설정'!$C$14*'설정'!$E$32,1)/$D9)^(-'설정'!$C$6),('설정'!$C$32*IF($A9>=31,1+'설정'!$C$14*'설정'!$E$32,1)/$D9)^(-'설정'!$C$7)),0)) | S9: =IF($E9*'설정'!$C$5*IF(('설정'!$C$33*IF($A9>=31,1+'설정'!$C$14*'설정'!$E$33,1)/$D9)<1,('설정'!$C$33*IF($A9>=31,1+'설정'!$C$14*'설정'!$E$33,1)/$D9)^(-'설정'!$C$6),('설정'!$C$33*IF($A9>=31,1+'설정'!$C$14*'설정'!$E$33,1)/$D9)^(-'설정'!$C$7))>('설정'!$C$4+'설정'!$F$33),"실패",ROUND($E9*'설정'!$C$5*IF(('설정'!$C$33*IF($A9>=31,1+'설정'!$C$14*'설정'!$E$33,1)/$D9)<1,('설정'!$C$33*IF($A9>=31,1+'설정'!$C$14*'설정'!$E$33,1)/$D9)^(-'설정'!$C$6),('설정'!$C$33*IF($A9>=31,1+'설정'!$C$14*'설정'!$E$33,1)/$D9)^(-'설정'!$C$7)),0)) | T9: =IF($E9*'설정'!$C$5*IF(('설정'!$C$34*IF($A9>=31,1+'설정'!$C$14*'설정'!$E$34,1)/$D9)<1,('설정'!$C$34*IF($A9>=31,1+'설정'!$C$14*'설정'!$E$34,1)/$D9)^(-'설정'!$C$6),('설정'!$C$34*IF($A9>=31,1+'설정'!$C$14*'설정'!$E$34,1)/$D9)^(-'설정'!$C$7))>('설정'!$C$4+'설정'!$F$34),"실패",ROUND($E9*'설정'!$C$5*IF(('설정'!$C$34*IF($A9>=31,1+'설정'!$C$14*'설정'!$E$34,1)/$D9)<1,('설정'!$C$34*IF($A9>=31,1+'설정'!$C$14*'설정'!$E$34,1)/$D9)^(-'설정'!$C$6),('설정'!$C$34*IF($A9>=31,1+'설정'!$C$14*'설정'!$E$34,1)/$D9)^(-'설정'!$C$7)),0)) | U9: =IF($E9*'설정'!$C$5*IF(('설정'!$C$35*IF($A9>=31,1+'설정'!$C$14*'설정'!$E$35,1)/$D9)<1,('설정'!$C$35*IF($A9>=31,1+'설정'!$C$14*'설정'!$E$35,1)/$D9)^(-'설정'!$C$6),('설정'!$C$35*IF($A9>=31,1+'설정'!$C$14*'설정'!$E$35,1)/$D9)^(-'설정'!$C$7))>('설정'!$C$4+'설정'!$F$35),"실패",ROUND($E9*'설정'!$C$5*IF(('설정'!$C$35*IF($A9>=31,1+'설정'!$C$14*'설정'!$E$35,1)/$D9)<1,('설정'!$C$35*IF($A9>=31,1+'설정'!$C$14*'설정'!$E$35,1)/$D9)^(-'설정'!$C$6),('설정'!$C$35*IF($A9>=31,1+'설정'!$C$14*'설정'!$E$35,1)/$D9)^(-'설정'!$C$7)),0)) | V9: =IF($E9*'설정'!$C$5*IF(('설정'!$C$36*IF($A9>=31,1+'설정'!$C$14*'설정'!$E$36,1)/$D9)<1,('설정'!$C$36*IF($A9>=31,1+'설정'!$C$14*'설정'!$E$36,1)/$D9)^(-'설정'!$C$6),('설정'!$C$36*IF($A9>=31,1+'설정'!$C$14*'설정'!$E$36,1)/$D9)^(-'설정'!$C$7))>('설정'!$C$4+'설정'!$F$36),"실패",ROUND($E9*'설정'!$C$5*IF(('설정'!$C$36*IF($A9>=31,1+'설정'!$C$14*'설정'!$E$36,1)/$D9)<1,('설정'!$C$36*IF($A9>=31,1+'설정'!$C$14*'설정'!$E$36,1)/$D9)^(-'설정'!$C$6),('설정'!$C$36*IF($A9>=31,1+'설정'!$C$14*'설정'!$E$36,1)/$D9)^(-'설정'!$C$7)),0)) | W9: =IF($E9*'설정'!$C$5*IF(('설정'!$C$37*IF($A9>=31,1+'설정'!$C$14*'설정'!$E$37,1)/$D9)<1,('설정'!$C$37*IF($A9>=31,1+'설정'!$C$14*'설정'!$E$37,1)/$D9)^(-'설정'!$C$6),('설정'!$C$37*IF($A9>=31,1+'설정'!$C$14*'설정'!$E$37,1)/$D9)^(-'설정'!$C$7))>('설정'!$C$4+'설정'!$F$37),"실패",ROUND($E9*'설정'!$C$5*IF(('설정'!$C$37*IF($A9>=31,1+'설정'!$C$14*'설정'!$E$37,1)/$D9)<1,('설정'!$C$37*IF($A9>=31,1+'설정'!$C$14*'설정'!$E$37,1)/$D9)^(-'설정'!$C$6),('설정'!$C$37*IF($A9>=31,1+'설정'!$C$14*'설정'!$E$37,1)/$D9)^(-'설정'!$C$7)),0))
